[14/Apr/2016 12:41:22] DEBUG [django.db.backends:89] (0.001) QUERY = "\n            SELECT name, type FROM sqlite_master\n            WHERE type in ('table', 'view') AND NOT name='sqlite_sequence'\n            ORDER BY name" - PARAMS = (); args=None
[14/Apr/2016 12:41:22] DEBUG [django.db.backends:89] (0.000) QUERY = u'SELECT "django_migrations"."app", "django_migrations"."name" FROM "django_migrations"' - PARAMS = (); args=()
[14/Apr/2016 12:41:34] DEBUG [django.db.backends:89] (0.002) QUERY = u'SELECT "django_session"."session_key", "django_session"."session_data", "django_session"."expire_date" FROM "django_session" WHERE ("django_session"."session_key" = %s AND "django_session"."expire_date" > %s)' - PARAMS = (u'c8vxro96schiu1osvv555tida8ysjkw5', u'2016-04-14 12:41:34.189025'); args=('c8vxro96schiu1osvv555tida8ysjkw5', u'2016-04-14 12:41:34.189025')
[14/Apr/2016 12:41:34] DEBUG [django.db.backends:89] (0.000) QUERY = u'SELECT "auth_user"."id", "auth_user"."password", "auth_user"."last_login", "auth_user"."is_superuser", "auth_user"."username", "auth_user"."first_name", "auth_user"."last_name", "auth_user"."email", "auth_user"."is_staff", "auth_user"."is_active", "auth_user"."date_joined" FROM "auth_user" WHERE "auth_user"."id" = %s' - PARAMS = (1,); args=(1,)
[14/Apr/2016 12:41:34] DEBUG [django.db.backends:89] (0.000) QUERY = u'SELECT "django_session"."session_key", "django_session"."session_data", "django_session"."expire_date" FROM "django_session" WHERE ("django_session"."session_key" = %s AND "django_session"."expire_date" > %s)' - PARAMS = (u'c8vxro96schiu1osvv555tida8ysjkw5', u'2016-04-14 12:41:34.198448'); args=('c8vxro96schiu1osvv555tida8ysjkw5', u'2016-04-14 12:41:34.198448')
[14/Apr/2016 12:41:34] DEBUG [django.db.backends:89] (0.000) QUERY = u'SELECT "auth_user"."id", "auth_user"."password", "auth_user"."last_login", "auth_user"."is_superuser", "auth_user"."username", "auth_user"."first_name", "auth_user"."last_name", "auth_user"."email", "auth_user"."is_staff", "auth_user"."is_active", "auth_user"."date_joined" FROM "auth_user" WHERE "auth_user"."id" = %s' - PARAMS = (1,); args=(1,)
[14/Apr/2016 12:41:34] DEBUG [django.db.backends:89] (0.001) QUERY = u'SELECT "django_admin_log"."id", "django_admin_log"."action_time", "django_admin_log"."user_id", "django_admin_log"."content_type_id", "django_admin_log"."object_id", "django_admin_log"."object_repr", "django_admin_log"."action_flag", "django_admin_log"."change_message", "auth_user"."id", "auth_user"."password", "auth_user"."last_login", "auth_user"."is_superuser", "auth_user"."username", "auth_user"."first_name", "auth_user"."last_name", "auth_user"."email", "auth_user"."is_staff", "auth_user"."is_active", "auth_user"."date_joined", "django_content_type"."id", "django_content_type"."app_label", "django_content_type"."model" FROM "django_admin_log" INNER JOIN "auth_user" ON ( "django_admin_log"."user_id" = "auth_user"."id" ) LEFT OUTER JOIN "django_content_type" ON ( "django_admin_log"."content_type_id" = "django_content_type"."id" ) WHERE "django_admin_log"."user_id" = %s ORDER BY "django_admin_log"."action_time" DESC LIMIT 10' - PARAMS = (1,); args=(1,)
[14/Apr/2016 12:41:41] WARNING [django.request:170] Not Found: /
[14/Apr/2016 16:02:51] ERROR [django.request:256] Internal Server Error: /startnow/
Traceback (most recent call last):
  File "/Library/Frameworks/Python.framework/Versions/2.7/lib/python2.7/site-packages/django/core/handlers/base.py", line 132, in get_response
    response = wrapped_callback(request, *callback_args, **callback_kwargs)
  File "/Users/madhurn/PycharmProjects/UMTSCellMap/startnow/views.py", line 7, in index
    template = loader.get_template('startnow/index.html')
  File "/Library/Frameworks/Python.framework/Versions/2.7/lib/python2.7/site-packages/django/template/loader.py", line 35, in get_template
    return engine.get_template(template_name, dirs)
  File "/Library/Frameworks/Python.framework/Versions/2.7/lib/python2.7/site-packages/django/template/backends/django.py", line 30, in get_template
    return Template(self.engine.get_template(template_name, dirs))
  File "/Library/Frameworks/Python.framework/Versions/2.7/lib/python2.7/site-packages/django/template/engine.py", line 167, in get_template
    template, origin = self.find_template(template_name, dirs)
  File "/Library/Frameworks/Python.framework/Versions/2.7/lib/python2.7/site-packages/django/template/engine.py", line 141, in find_template
    source, display_name = loader(name, dirs)
  File "/Library/Frameworks/Python.framework/Versions/2.7/lib/python2.7/site-packages/django/template/loaders/base.py", line 13, in __call__
    return self.load_template(template_name, template_dirs)
  File "/Library/Frameworks/Python.framework/Versions/2.7/lib/python2.7/site-packages/django/template/loaders/base.py", line 23, in load_template
    template = Template(source, origin, template_name, self.engine)
  File "/Library/Frameworks/Python.framework/Versions/2.7/lib/python2.7/site-packages/django/template/base.py", line 191, in __init__
    self.nodelist = engine.compile_string(template_string, origin)
  File "/Library/Frameworks/Python.framework/Versions/2.7/lib/python2.7/site-packages/django/template/engine.py", line 261, in compile_string
    return parser.parse()
  File "/Library/Frameworks/Python.framework/Versions/2.7/lib/python2.7/site-packages/django/template/base.py", line 342, in parse
    compiled_result = compile_func(self, token)
  File "/Library/Frameworks/Python.framework/Versions/2.7/lib/python2.7/site-packages/django/template/loader_tags.py", line 184, in do_block
    nodelist = parser.parse(('endblock',))
  File "/Library/Frameworks/Python.framework/Versions/2.7/lib/python2.7/site-packages/django/template/base.py", line 349, in parse
    self.unclosed_block_tag(parse_until)
  File "/Library/Frameworks/Python.framework/Versions/2.7/lib/python2.7/site-packages/django/template/debug.py", line 65, in unclosed_block_tag
    raise self.source_error(source, msg)
TemplateSyntaxError: Unclosed tag 'block'. Looking for one of: endblock 
[15/Apr/2016 03:10:06] WARNING [django.request:98] Forbidden (CSRF token missing or incorrect.): /startnow/
[15/Apr/2016 03:10:36] WARNING [django.request:98] Forbidden (CSRF token missing or incorrect.): /startnow/
[15/Apr/2016 03:10:40] WARNING [django.request:98] Forbidden (CSRF token missing or incorrect.): /startnow/
[15/Apr/2016 03:10:47] WARNING [django.request:98] Forbidden (CSRF token missing or incorrect.): /startnow/
[15/Apr/2016 03:11:57] WARNING [django.request:98] Forbidden (CSRF token missing or incorrect.): /startnow/
[15/Apr/2016 03:12:50] WARNING [django.request:98] Forbidden (CSRF token missing or incorrect.): /startnow/
[15/Apr/2016 03:13:52] WARNING [django.request:98] Forbidden (CSRF token missing or incorrect.): /startnow/
[15/Apr/2016 03:15:23] WARNING [django.request:170] Not Found: /
[15/Apr/2016 03:15:28] DEBUG [django.db.backends:89] (0.006) QUERY = u'SELECT "django_session"."session_key", "django_session"."session_data", "django_session"."expire_date" FROM "django_session" WHERE ("django_session"."session_key" = %s AND "django_session"."expire_date" > %s)' - PARAMS = (u'c8vxro96schiu1osvv555tida8ysjkw5', u'2016-04-15 03:15:28.762060'); args=('c8vxro96schiu1osvv555tida8ysjkw5', u'2016-04-15 03:15:28.762060')
[15/Apr/2016 03:15:28] DEBUG [django.db.backends:89] (0.001) QUERY = u'SELECT "auth_user"."id", "auth_user"."password", "auth_user"."last_login", "auth_user"."is_superuser", "auth_user"."username", "auth_user"."first_name", "auth_user"."last_name", "auth_user"."email", "auth_user"."is_staff", "auth_user"."is_active", "auth_user"."date_joined" FROM "auth_user" WHERE "auth_user"."id" = %s' - PARAMS = (1,); args=(1,)
[15/Apr/2016 03:15:28] DEBUG [django.db.backends:89] (0.001) QUERY = u'SELECT "django_admin_log"."id", "django_admin_log"."action_time", "django_admin_log"."user_id", "django_admin_log"."content_type_id", "django_admin_log"."object_id", "django_admin_log"."object_repr", "django_admin_log"."action_flag", "django_admin_log"."change_message", "auth_user"."id", "auth_user"."password", "auth_user"."last_login", "auth_user"."is_superuser", "auth_user"."username", "auth_user"."first_name", "auth_user"."last_name", "auth_user"."email", "auth_user"."is_staff", "auth_user"."is_active", "auth_user"."date_joined", "django_content_type"."id", "django_content_type"."app_label", "django_content_type"."model" FROM "django_admin_log" INNER JOIN "auth_user" ON ( "django_admin_log"."user_id" = "auth_user"."id" ) LEFT OUTER JOIN "django_content_type" ON ( "django_admin_log"."content_type_id" = "django_content_type"."id" ) WHERE "django_admin_log"."user_id" = %s ORDER BY "django_admin_log"."action_time" DESC LIMIT 10' - PARAMS = (1,); args=(1,)
[15/Apr/2016 03:15:34] DEBUG [django.db.backends:89] (0.001) QUERY = u'SELECT "django_session"."session_key", "django_session"."session_data", "django_session"."expire_date" FROM "django_session" WHERE ("django_session"."session_key" = %s AND "django_session"."expire_date" > %s)' - PARAMS = (u'c8vxro96schiu1osvv555tida8ysjkw5', u'2016-04-15 03:15:34.447319'); args=('c8vxro96schiu1osvv555tida8ysjkw5', u'2016-04-15 03:15:34.447319')
[15/Apr/2016 03:15:34] DEBUG [django.db.backends:89] (0.000) QUERY = u'SELECT "auth_user"."id", "auth_user"."password", "auth_user"."last_login", "auth_user"."is_superuser", "auth_user"."username", "auth_user"."first_name", "auth_user"."last_name", "auth_user"."email", "auth_user"."is_staff", "auth_user"."is_active", "auth_user"."date_joined" FROM "auth_user" WHERE "auth_user"."id" = %s' - PARAMS = (1,); args=(1,)
[15/Apr/2016 03:15:34] DEBUG [django.db.backends:89] (0.000) QUERY = u'SELECT "django_session"."session_key", "django_session"."session_data", "django_session"."expire_date" FROM "django_session" WHERE "django_session"."session_key" = %s' - PARAMS = (u'c8vxro96schiu1osvv555tida8ysjkw5',); args=('c8vxro96schiu1osvv555tida8ysjkw5',)
[15/Apr/2016 03:15:34] DEBUG [django.db.backends:89] (0.000) QUERY = u'BEGIN' - PARAMS = (); args=None
[15/Apr/2016 03:15:34] DEBUG [django.db.backends:89] (0.001) QUERY = u'DELETE FROM "django_session" WHERE "django_session"."session_key" IN (%s)' - PARAMS = (u'c8vxro96schiu1osvv555tida8ysjkw5',); args=(u'c8vxro96schiu1osvv555tida8ysjkw5',)
[15/Apr/2016 03:15:39] DEBUG [django.db.backends:89] (0.001) QUERY = u'SELECT "auth_user"."id", "auth_user"."password", "auth_user"."last_login", "auth_user"."is_superuser", "auth_user"."username", "auth_user"."first_name", "auth_user"."last_name", "auth_user"."email", "auth_user"."is_staff", "auth_user"."is_active", "auth_user"."date_joined" FROM "auth_user" WHERE "auth_user"."username" = %s' - PARAMS = (u'admin',); args=(u'admin',)
[15/Apr/2016 03:15:39] DEBUG [django.db.backends:89] (0.000) QUERY = u'SELECT (1) AS "a" FROM "django_session" WHERE "django_session"."session_key" = %s LIMIT 1' - PARAMS = (u'1zbw2zkg38eimdazf58zrrex548i868u',); args=(u'1zbw2zkg38eimdazf58zrrex548i868u',)
[15/Apr/2016 03:15:39] DEBUG [django.db.backends:89] (0.000) QUERY = u'BEGIN' - PARAMS = (); args=None
[15/Apr/2016 03:15:39] DEBUG [django.db.backends:89] (0.000) QUERY = u'INSERT INTO "django_session" ("session_key", "session_data", "expire_date") SELECT %s AS "session_key", %s AS "session_data", %s AS "expire_date"' - PARAMS = (u'1zbw2zkg38eimdazf58zrrex548i868u', u'YWUwNjE0ODgyYWY4ZTMzZDNhNTlhMTlhYTJhMTU3ZTAxZTMzYmIyMDp7fQ==', u'2016-04-29 03:15:39.607547'); args=(u'1zbw2zkg38eimdazf58zrrex548i868u', u'YWUwNjE0ODgyYWY4ZTMzZDNhNTlhMTlhYTJhMTU3ZTAxZTMzYmIyMDp7fQ==', u'2016-04-29 03:15:39.607547')
[15/Apr/2016 03:15:39] DEBUG [django.db.backends:89] (0.000) QUERY = u'SELECT "django_session"."session_key", "django_session"."session_data", "django_session"."expire_date" FROM "django_session" WHERE "django_session"."session_key" = %s' - PARAMS = (u'1zbw2zkg38eimdazf58zrrex548i868u',); args=(u'1zbw2zkg38eimdazf58zrrex548i868u',)
[15/Apr/2016 03:15:39] DEBUG [django.db.backends:89] (0.000) QUERY = u'BEGIN' - PARAMS = (); args=None
[15/Apr/2016 03:15:39] DEBUG [django.db.backends:89] (0.000) QUERY = u'DELETE FROM "django_session" WHERE "django_session"."session_key" IN (%s)' - PARAMS = (u'1zbw2zkg38eimdazf58zrrex548i868u',); args=(u'1zbw2zkg38eimdazf58zrrex548i868u',)
[15/Apr/2016 03:15:39] DEBUG [django.db.backends:89] (0.000) QUERY = u'BEGIN' - PARAMS = (); args=None
[15/Apr/2016 03:15:39] DEBUG [django.db.backends:89] (0.000) QUERY = u'UPDATE "auth_user" SET "last_login" = %s WHERE "auth_user"."id" = %s' - PARAMS = (u'2016-04-15 03:15:39.616735', 1); args=(u'2016-04-15 03:15:39.616735', 1)
[15/Apr/2016 03:15:39] DEBUG [django.db.backends:89] (0.000) QUERY = u'BEGIN' - PARAMS = (); args=None
[15/Apr/2016 03:15:39] DEBUG [django.db.backends:89] (0.000) QUERY = u'UPDATE "django_session" SET "session_data" = %s, "expire_date" = %s WHERE "django_session"."session_key" = %s' - PARAMS = (u'YzNlNjA3OTE3ZDQ4YTU3MDYwNThjMmI0NmU3MGY0YjhjN2I0Y2M5ZTp7Il9hdXRoX3VzZXJfaGFzaCI6IjY1OWU4OWNkZjM3YzJiZWE2ZWM4ZDcxNWM0MDNhYjYzNmM5NDM0NzAiLCJfYXV0aF91c2VyX2JhY2tlbmQiOiJkamFuZ28uY29udHJpYi5hdXRoLmJhY2tlbmRzLk1vZGVsQmFja2VuZCIsIl9hdXRoX3VzZXJfaWQiOiIxIn0=', u'2016-04-29 03:15:39.621187', u'1zbw2zkg38eimdazf58zrrex548i868u'); args=(u'YzNlNjA3OTE3ZDQ4YTU3MDYwNThjMmI0NmU3MGY0YjhjN2I0Y2M5ZTp7Il9hdXRoX3VzZXJfaGFzaCI6IjY1OWU4OWNkZjM3YzJiZWE2ZWM4ZDcxNWM0MDNhYjYzNmM5NDM0NzAiLCJfYXV0aF91c2VyX2JhY2tlbmQiOiJkamFuZ28uY29udHJpYi5hdXRoLmJhY2tlbmRzLk1vZGVsQmFja2VuZCIsIl9hdXRoX3VzZXJfaWQiOiIxIn0=', u'2016-04-29 03:15:39.621187', u'1zbw2zkg38eimdazf58zrrex548i868u')
[15/Apr/2016 03:15:39] DEBUG [django.db.backends:89] (0.000) QUERY = u'INSERT INTO "django_session" ("session_key", "session_data", "expire_date") SELECT %s AS "session_key", %s AS "session_data", %s AS "expire_date"' - PARAMS = (u'1zbw2zkg38eimdazf58zrrex548i868u', u'YzNlNjA3OTE3ZDQ4YTU3MDYwNThjMmI0NmU3MGY0YjhjN2I0Y2M5ZTp7Il9hdXRoX3VzZXJfaGFzaCI6IjY1OWU4OWNkZjM3YzJiZWE2ZWM4ZDcxNWM0MDNhYjYzNmM5NDM0NzAiLCJfYXV0aF91c2VyX2JhY2tlbmQiOiJkamFuZ28uY29udHJpYi5hdXRoLmJhY2tlbmRzLk1vZGVsQmFja2VuZCIsIl9hdXRoX3VzZXJfaWQiOiIxIn0=', u'2016-04-29 03:15:39.621187'); args=(u'1zbw2zkg38eimdazf58zrrex548i868u', u'YzNlNjA3OTE3ZDQ4YTU3MDYwNThjMmI0NmU3MGY0YjhjN2I0Y2M5ZTp7Il9hdXRoX3VzZXJfaGFzaCI6IjY1OWU4OWNkZjM3YzJiZWE2ZWM4ZDcxNWM0MDNhYjYzNmM5NDM0NzAiLCJfYXV0aF91c2VyX2JhY2tlbmQiOiJkamFuZ28uY29udHJpYi5hdXRoLmJhY2tlbmRzLk1vZGVsQmFja2VuZCIsIl9hdXRoX3VzZXJfaWQiOiIxIn0=', u'2016-04-29 03:15:39.621187')
[15/Apr/2016 03:15:39] DEBUG [django.db.backends:89] (0.001) QUERY = u'SELECT "django_session"."session_key", "django_session"."session_data", "django_session"."expire_date" FROM "django_session" WHERE ("django_session"."session_key" = %s AND "django_session"."expire_date" > %s)' - PARAMS = (u'1zbw2zkg38eimdazf58zrrex548i868u', u'2016-04-15 03:15:39.628955'); args=('1zbw2zkg38eimdazf58zrrex548i868u', u'2016-04-15 03:15:39.628955')
[15/Apr/2016 03:15:39] DEBUG [django.db.backends:89] (0.000) QUERY = u'SELECT "auth_user"."id", "auth_user"."password", "auth_user"."last_login", "auth_user"."is_superuser", "auth_user"."username", "auth_user"."first_name", "auth_user"."last_name", "auth_user"."email", "auth_user"."is_staff", "auth_user"."is_active", "auth_user"."date_joined" FROM "auth_user" WHERE "auth_user"."id" = %s' - PARAMS = (1,); args=(1,)
[15/Apr/2016 03:15:39] DEBUG [django.db.backends:89] (0.001) QUERY = u'SELECT "django_admin_log"."id", "django_admin_log"."action_time", "django_admin_log"."user_id", "django_admin_log"."content_type_id", "django_admin_log"."object_id", "django_admin_log"."object_repr", "django_admin_log"."action_flag", "django_admin_log"."change_message", "auth_user"."id", "auth_user"."password", "auth_user"."last_login", "auth_user"."is_superuser", "auth_user"."username", "auth_user"."first_name", "auth_user"."last_name", "auth_user"."email", "auth_user"."is_staff", "auth_user"."is_active", "auth_user"."date_joined", "django_content_type"."id", "django_content_type"."app_label", "django_content_type"."model" FROM "django_admin_log" INNER JOIN "auth_user" ON ( "django_admin_log"."user_id" = "auth_user"."id" ) LEFT OUTER JOIN "django_content_type" ON ( "django_admin_log"."content_type_id" = "django_content_type"."id" ) WHERE "django_admin_log"."user_id" = %s ORDER BY "django_admin_log"."action_time" DESC LIMIT 10' - PARAMS = (1,); args=(1,)
[15/Apr/2016 03:16:07] WARNING [django.request:98] Forbidden (CSRF token missing or incorrect.): /startnow/
[15/Apr/2016 03:16:11] WARNING [django.request:98] Forbidden (CSRF token missing or incorrect.): /startnow/
[15/Apr/2016 03:20:36] ERROR [django.request:256] Internal Server Error: /startnow/
Traceback (most recent call last):
  File "/Library/Frameworks/Python.framework/Versions/2.7/lib/python2.7/site-packages/django/core/handlers/base.py", line 132, in get_response
    response = wrapped_callback(request, *callback_args, **callback_kwargs)
  File "/Users/madhurn/PycharmProjects/UMTSCellMap/startnow/views.py", line 7, in index
    template = loader.get_template('startnow/index.html')
  File "/Library/Frameworks/Python.framework/Versions/2.7/lib/python2.7/site-packages/django/template/loader.py", line 35, in get_template
    return engine.get_template(template_name, dirs)
  File "/Library/Frameworks/Python.framework/Versions/2.7/lib/python2.7/site-packages/django/template/backends/django.py", line 30, in get_template
    return Template(self.engine.get_template(template_name, dirs))
  File "/Library/Frameworks/Python.framework/Versions/2.7/lib/python2.7/site-packages/django/template/engine.py", line 167, in get_template
    template, origin = self.find_template(template_name, dirs)
  File "/Library/Frameworks/Python.framework/Versions/2.7/lib/python2.7/site-packages/django/template/engine.py", line 141, in find_template
    source, display_name = loader(name, dirs)
  File "/Library/Frameworks/Python.framework/Versions/2.7/lib/python2.7/site-packages/django/template/loaders/base.py", line 13, in __call__
    return self.load_template(template_name, template_dirs)
  File "/Library/Frameworks/Python.framework/Versions/2.7/lib/python2.7/site-packages/django/template/loaders/base.py", line 23, in load_template
    template = Template(source, origin, template_name, self.engine)
  File "/Library/Frameworks/Python.framework/Versions/2.7/lib/python2.7/site-packages/django/template/base.py", line 191, in __init__
    self.nodelist = engine.compile_string(template_string, origin)
  File "/Library/Frameworks/Python.framework/Versions/2.7/lib/python2.7/site-packages/django/template/engine.py", line 261, in compile_string
    return parser.parse()
  File "/Library/Frameworks/Python.framework/Versions/2.7/lib/python2.7/site-packages/django/template/base.py", line 340, in parse
    self.invalid_block_tag(token, command, parse_until)
  File "/Library/Frameworks/Python.framework/Versions/2.7/lib/python2.7/site-packages/django/template/base.py", line 396, in invalid_block_tag
    raise self.error(token, "Invalid block tag: '%s'" % command)
TemplateSyntaxError: Invalid block tag: 'laod'
[15/Apr/2016 03:20:49] WARNING [django.request:98] Forbidden (CSRF token missing or incorrect.): /startnow/
[15/Apr/2016 03:22:56] DEBUG [django.db.backends:89] (0.001) QUERY = "\n            SELECT name, type FROM sqlite_master\n            WHERE type in ('table', 'view') AND NOT name='sqlite_sequence'\n            ORDER BY name" - PARAMS = (); args=None
[15/Apr/2016 03:22:56] DEBUG [django.db.backends:89] (0.000) QUERY = u'SELECT "django_migrations"."app", "django_migrations"."name" FROM "django_migrations"' - PARAMS = (); args=()
[15/Apr/2016 03:23:02] WARNING [django.request:98] Forbidden (CSRF token missing or incorrect.): /startnow/
[15/Apr/2016 03:23:39] DEBUG [django.db.backends:89] (0.001) QUERY = "\n            SELECT name, type FROM sqlite_master\n            WHERE type in ('table', 'view') AND NOT name='sqlite_sequence'\n            ORDER BY name" - PARAMS = (); args=None
[15/Apr/2016 03:23:39] DEBUG [django.db.backends:89] (0.000) QUERY = u'SELECT "django_migrations"."app", "django_migrations"."name" FROM "django_migrations"' - PARAMS = (); args=()
[15/Apr/2016 03:23:46] WARNING [django.request:98] Forbidden (CSRF token missing or incorrect.): /startnow/
[15/Apr/2016 03:23:50] WARNING [django.request:98] Forbidden (CSRF token missing or incorrect.): /startnow/
[15/Apr/2016 03:24:06] DEBUG [django.db.backends:89] (0.001) QUERY = "\n            SELECT name, type FROM sqlite_master\n            WHERE type in ('table', 'view') AND NOT name='sqlite_sequence'\n            ORDER BY name" - PARAMS = (); args=None
[15/Apr/2016 03:24:06] DEBUG [django.db.backends:89] (0.000) QUERY = u'SELECT "django_migrations"."app", "django_migrations"."name" FROM "django_migrations"' - PARAMS = (); args=()
[15/Apr/2016 03:24:09] WARNING [django.request:98] Forbidden (CSRF token missing or incorrect.): /startnow/
[15/Apr/2016 03:30:20] DEBUG [django.db.backends:89] (0.001) QUERY = "\n            SELECT name, type FROM sqlite_master\n            WHERE type in ('table', 'view') AND NOT name='sqlite_sequence'\n            ORDER BY name" - PARAMS = (); args=None
[15/Apr/2016 03:30:20] DEBUG [django.db.backends:89] (0.000) QUERY = u'SELECT "django_migrations"."app", "django_migrations"."name" FROM "django_migrations"' - PARAMS = (); args=()
[15/Apr/2016 03:36:53] ERROR [django.request:256] Internal Server Error: /startnow/
Traceback (most recent call last):
  File "/Library/Frameworks/Python.framework/Versions/2.7/lib/python2.7/site-packages/django/core/handlers/base.py", line 119, in get_response
    resolver_match = resolver.resolve(request.path_info)
  File "/Library/Frameworks/Python.framework/Versions/2.7/lib/python2.7/site-packages/django/core/urlresolvers.py", line 365, in resolve
    for pattern in self.url_patterns:
  File "/Library/Frameworks/Python.framework/Versions/2.7/lib/python2.7/site-packages/django/core/urlresolvers.py", line 401, in url_patterns
    patterns = getattr(self.urlconf_module, "urlpatterns", self.urlconf_module)
  File "/Library/Frameworks/Python.framework/Versions/2.7/lib/python2.7/site-packages/django/core/urlresolvers.py", line 395, in urlconf_module
    self._urlconf_module = import_module(self.urlconf_name)
  File "/opt/local/Library/Frameworks/Python.framework/Versions/2.7/lib/python2.7/importlib/__init__.py", line 37, in import_module
    __import__(name)
  File "/Users/madhurn/PycharmProjects/UMTSCellMap/UMTSCellMap/urls.py", line 24, in <module>
    url(r'^startnow/', include('startnow.urls', namespace="startnow")),
  File "/Library/Frameworks/Python.framework/Versions/2.7/lib/python2.7/site-packages/django/conf/urls/__init__.py", line 33, in include
    urlconf_module = import_module(urlconf_module)
  File "/opt/local/Library/Frameworks/Python.framework/Versions/2.7/lib/python2.7/importlib/__init__.py", line 37, in import_module
    __import__(name)
  File "/Users/madhurn/PycharmProjects/UMTSCellMap/startnow/urls.py", line 3, in <module>
    from views import empty
  File "/Users/madhurn/PycharmProjects/UMTSCellMap/startnow/views.py", line 11
    handlePostMethod(request):
                             ^
SyntaxError: invalid syntax
[15/Apr/2016 03:40:31] DEBUG [django.db.backends:89] (0.001) QUERY = "\n            SELECT name, type FROM sqlite_master\n            WHERE type in ('table', 'view') AND NOT name='sqlite_sequence'\n            ORDER BY name" - PARAMS = (); args=None
[15/Apr/2016 03:40:31] DEBUG [django.db.backends:89] (0.000) QUERY = u'SELECT "django_migrations"."app", "django_migrations"."name" FROM "django_migrations"' - PARAMS = (); args=()
[15/Apr/2016 05:05:22] WARNING [django.request:170] Not Found: /startnow/index
[15/Apr/2016 05:06:17] WARNING [django.request:170] Not Found: /
[15/Apr/2016 05:06:43] WARNING [django.request:170] Not Found: /startnow/startnow
[15/Apr/2016 05:06:59] ERROR [django.request:256] Internal Server Error: /startnow
Traceback (most recent call last):
  File "/Library/Frameworks/Python.framework/Versions/2.7/lib/python2.7/site-packages/django/core/handlers/base.py", line 108, in get_response
    response = middleware_method(request)
  File "/Library/Frameworks/Python.framework/Versions/2.7/lib/python2.7/site-packages/django/middleware/common.py", line 84, in process_request
    "settings.") % (new_url[0], new_url[1]))
RuntimeError: You called this URL via POST, but the URL doesn't end in a slash and you have APPEND_SLASH set. Django can't redirect to the slash URL while maintaining POST data. Change your form to point to 127.0.0.1:8000/startnow/ (note the trailing slash), or set APPEND_SLASH=False in your Django settings.
[15/Apr/2016 05:26:01] DEBUG [django.db.backends:89] (0.001) QUERY = "\n            SELECT name, type FROM sqlite_master\n            WHERE type in ('table', 'view') AND NOT name='sqlite_sequence'\n            ORDER BY name" - PARAMS = (); args=None
[15/Apr/2016 05:26:01] DEBUG [django.db.backends:89] (0.000) QUERY = u'SELECT "django_migrations"."app", "django_migrations"."name" FROM "django_migrations"' - PARAMS = (); args=()
[15/Apr/2016 08:21:01] ERROR [django.request:256] Internal Server Error: /startnow/
Traceback (most recent call last):
  File "/Library/Frameworks/Python.framework/Versions/2.7/lib/python2.7/site-packages/django/core/handlers/base.py", line 119, in get_response
    resolver_match = resolver.resolve(request.path_info)
  File "/Library/Frameworks/Python.framework/Versions/2.7/lib/python2.7/site-packages/django/core/urlresolvers.py", line 365, in resolve
    for pattern in self.url_patterns:
  File "/Library/Frameworks/Python.framework/Versions/2.7/lib/python2.7/site-packages/django/core/urlresolvers.py", line 401, in url_patterns
    patterns = getattr(self.urlconf_module, "urlpatterns", self.urlconf_module)
  File "/Library/Frameworks/Python.framework/Versions/2.7/lib/python2.7/site-packages/django/core/urlresolvers.py", line 395, in urlconf_module
    self._urlconf_module = import_module(self.urlconf_name)
  File "/opt/local/Library/Frameworks/Python.framework/Versions/2.7/lib/python2.7/importlib/__init__.py", line 37, in import_module
    __import__(name)
  File "/Users/madhurn/PycharmProjects/UMTSCellMap/UMTSCellMap/urls.py", line 24, in <module>
    url(r'^startnow/', include('startnow.urls', namespace="startnow")),
  File "/Library/Frameworks/Python.framework/Versions/2.7/lib/python2.7/site-packages/django/conf/urls/__init__.py", line 33, in include
    urlconf_module = import_module(urlconf_module)
  File "/opt/local/Library/Frameworks/Python.framework/Versions/2.7/lib/python2.7/importlib/__init__.py", line 37, in import_module
    __import__(name)
  File "/Users/madhurn/PycharmProjects/UMTSCellMap/startnow/urls.py", line 3, in <module>
    from views import empty
  File "/Users/madhurn/PycharmProjects/UMTSCellMap/startnow/views.py", line 4, in <module>
    from startnow import  Scheduler
  File "/Users/madhurn/PycharmProjects/UMTSCellMap/startnow/startnow.py", line 27
    def update_time_in_url(self, str, time)
                                          ^
SyntaxError: invalid syntax
[15/Apr/2016 08:21:14] ERROR [django.request:256] Internal Server Error: /startnow/
Traceback (most recent call last):
  File "/Library/Frameworks/Python.framework/Versions/2.7/lib/python2.7/site-packages/django/core/handlers/base.py", line 119, in get_response
    resolver_match = resolver.resolve(request.path_info)
  File "/Library/Frameworks/Python.framework/Versions/2.7/lib/python2.7/site-packages/django/core/urlresolvers.py", line 365, in resolve
    for pattern in self.url_patterns:
  File "/Library/Frameworks/Python.framework/Versions/2.7/lib/python2.7/site-packages/django/core/urlresolvers.py", line 401, in url_patterns
    patterns = getattr(self.urlconf_module, "urlpatterns", self.urlconf_module)
  File "/Library/Frameworks/Python.framework/Versions/2.7/lib/python2.7/site-packages/django/core/urlresolvers.py", line 395, in urlconf_module
    self._urlconf_module = import_module(self.urlconf_name)
  File "/opt/local/Library/Frameworks/Python.framework/Versions/2.7/lib/python2.7/importlib/__init__.py", line 37, in import_module
    __import__(name)
  File "/Users/madhurn/PycharmProjects/UMTSCellMap/UMTSCellMap/urls.py", line 24, in <module>
    url(r'^startnow/', include('startnow.urls', namespace="startnow")),
  File "/Library/Frameworks/Python.framework/Versions/2.7/lib/python2.7/site-packages/django/conf/urls/__init__.py", line 33, in include
    urlconf_module = import_module(urlconf_module)
  File "/opt/local/Library/Frameworks/Python.framework/Versions/2.7/lib/python2.7/importlib/__init__.py", line 37, in import_module
    __import__(name)
  File "/Users/madhurn/PycharmProjects/UMTSCellMap/startnow/urls.py", line 3, in <module>
    from views import empty
  File "/Users/madhurn/PycharmProjects/UMTSCellMap/startnow/views.py", line 4, in <module>
    from startnow import  Scheduler
  File "/Users/madhurn/PycharmProjects/UMTSCellMap/startnow/startnow.py", line 37
    def get_schedule(self)
                         ^
SyntaxError: invalid syntax
[15/Apr/2016 08:21:16] ERROR [django.request:256] Internal Server Error: /startnow/
Traceback (most recent call last):
  File "/Library/Frameworks/Python.framework/Versions/2.7/lib/python2.7/site-packages/django/core/handlers/base.py", line 119, in get_response
    resolver_match = resolver.resolve(request.path_info)
  File "/Library/Frameworks/Python.framework/Versions/2.7/lib/python2.7/site-packages/django/core/urlresolvers.py", line 365, in resolve
    for pattern in self.url_patterns:
  File "/Library/Frameworks/Python.framework/Versions/2.7/lib/python2.7/site-packages/django/core/urlresolvers.py", line 401, in url_patterns
    patterns = getattr(self.urlconf_module, "urlpatterns", self.urlconf_module)
  File "/Library/Frameworks/Python.framework/Versions/2.7/lib/python2.7/site-packages/django/core/urlresolvers.py", line 395, in urlconf_module
    self._urlconf_module = import_module(self.urlconf_name)
  File "/opt/local/Library/Frameworks/Python.framework/Versions/2.7/lib/python2.7/importlib/__init__.py", line 37, in import_module
    __import__(name)
  File "/Users/madhurn/PycharmProjects/UMTSCellMap/UMTSCellMap/urls.py", line 24, in <module>
    url(r'^startnow/', include('startnow.urls', namespace="startnow")),
  File "/Library/Frameworks/Python.framework/Versions/2.7/lib/python2.7/site-packages/django/conf/urls/__init__.py", line 33, in include
    urlconf_module = import_module(urlconf_module)
  File "/opt/local/Library/Frameworks/Python.framework/Versions/2.7/lib/python2.7/importlib/__init__.py", line 37, in import_module
    __import__(name)
  File "/Users/madhurn/PycharmProjects/UMTSCellMap/startnow/urls.py", line 3, in <module>
    from views import empty
  File "/Users/madhurn/PycharmProjects/UMTSCellMap/startnow/views.py", line 4, in <module>
    from startnow import  Scheduler
  File "/Users/madhurn/PycharmProjects/UMTSCellMap/startnow/startnow.py", line 37
    def get_schedule(self)
                         ^
SyntaxError: invalid syntax
[15/Apr/2016 08:21:17] ERROR [django.request:256] Internal Server Error: /startnow/
Traceback (most recent call last):
  File "/Library/Frameworks/Python.framework/Versions/2.7/lib/python2.7/site-packages/django/core/handlers/base.py", line 119, in get_response
    resolver_match = resolver.resolve(request.path_info)
  File "/Library/Frameworks/Python.framework/Versions/2.7/lib/python2.7/site-packages/django/core/urlresolvers.py", line 365, in resolve
    for pattern in self.url_patterns:
  File "/Library/Frameworks/Python.framework/Versions/2.7/lib/python2.7/site-packages/django/core/urlresolvers.py", line 401, in url_patterns
    patterns = getattr(self.urlconf_module, "urlpatterns", self.urlconf_module)
  File "/Library/Frameworks/Python.framework/Versions/2.7/lib/python2.7/site-packages/django/core/urlresolvers.py", line 395, in urlconf_module
    self._urlconf_module = import_module(self.urlconf_name)
  File "/opt/local/Library/Frameworks/Python.framework/Versions/2.7/lib/python2.7/importlib/__init__.py", line 37, in import_module
    __import__(name)
  File "/Users/madhurn/PycharmProjects/UMTSCellMap/UMTSCellMap/urls.py", line 24, in <module>
    url(r'^startnow/', include('startnow.urls', namespace="startnow")),
  File "/Library/Frameworks/Python.framework/Versions/2.7/lib/python2.7/site-packages/django/conf/urls/__init__.py", line 33, in include
    urlconf_module = import_module(urlconf_module)
  File "/opt/local/Library/Frameworks/Python.framework/Versions/2.7/lib/python2.7/importlib/__init__.py", line 37, in import_module
    __import__(name)
  File "/Users/madhurn/PycharmProjects/UMTSCellMap/startnow/urls.py", line 3, in <module>
    from views import empty
  File "/Users/madhurn/PycharmProjects/UMTSCellMap/startnow/views.py", line 4, in <module>
    from startnow import  Scheduler
  File "/Users/madhurn/PycharmProjects/UMTSCellMap/startnow/startnow.py", line 37
    def get_schedule(self)
                         ^
SyntaxError: invalid syntax
[15/Apr/2016 08:21:17] ERROR [django.request:256] Internal Server Error: /startnow/
Traceback (most recent call last):
  File "/Library/Frameworks/Python.framework/Versions/2.7/lib/python2.7/site-packages/django/core/handlers/base.py", line 119, in get_response
    resolver_match = resolver.resolve(request.path_info)
  File "/Library/Frameworks/Python.framework/Versions/2.7/lib/python2.7/site-packages/django/core/urlresolvers.py", line 365, in resolve
    for pattern in self.url_patterns:
  File "/Library/Frameworks/Python.framework/Versions/2.7/lib/python2.7/site-packages/django/core/urlresolvers.py", line 401, in url_patterns
    patterns = getattr(self.urlconf_module, "urlpatterns", self.urlconf_module)
  File "/Library/Frameworks/Python.framework/Versions/2.7/lib/python2.7/site-packages/django/core/urlresolvers.py", line 395, in urlconf_module
    self._urlconf_module = import_module(self.urlconf_name)
  File "/opt/local/Library/Frameworks/Python.framework/Versions/2.7/lib/python2.7/importlib/__init__.py", line 37, in import_module
    __import__(name)
  File "/Users/madhurn/PycharmProjects/UMTSCellMap/UMTSCellMap/urls.py", line 24, in <module>
    url(r'^startnow/', include('startnow.urls', namespace="startnow")),
  File "/Library/Frameworks/Python.framework/Versions/2.7/lib/python2.7/site-packages/django/conf/urls/__init__.py", line 33, in include
    urlconf_module = import_module(urlconf_module)
  File "/opt/local/Library/Frameworks/Python.framework/Versions/2.7/lib/python2.7/importlib/__init__.py", line 37, in import_module
    __import__(name)
  File "/Users/madhurn/PycharmProjects/UMTSCellMap/startnow/urls.py", line 3, in <module>
    from views import empty
  File "/Users/madhurn/PycharmProjects/UMTSCellMap/startnow/views.py", line 4, in <module>
    from startnow import  Scheduler
  File "/Users/madhurn/PycharmProjects/UMTSCellMap/startnow/startnow.py", line 37
    def get_schedule(self)
                         ^
SyntaxError: invalid syntax
[15/Apr/2016 08:21:18] ERROR [django.request:256] Internal Server Error: /startnow/
Traceback (most recent call last):
  File "/Library/Frameworks/Python.framework/Versions/2.7/lib/python2.7/site-packages/django/core/handlers/base.py", line 119, in get_response
    resolver_match = resolver.resolve(request.path_info)
  File "/Library/Frameworks/Python.framework/Versions/2.7/lib/python2.7/site-packages/django/core/urlresolvers.py", line 365, in resolve
    for pattern in self.url_patterns:
  File "/Library/Frameworks/Python.framework/Versions/2.7/lib/python2.7/site-packages/django/core/urlresolvers.py", line 401, in url_patterns
    patterns = getattr(self.urlconf_module, "urlpatterns", self.urlconf_module)
  File "/Library/Frameworks/Python.framework/Versions/2.7/lib/python2.7/site-packages/django/core/urlresolvers.py", line 395, in urlconf_module
    self._urlconf_module = import_module(self.urlconf_name)
  File "/opt/local/Library/Frameworks/Python.framework/Versions/2.7/lib/python2.7/importlib/__init__.py", line 37, in import_module
    __import__(name)
  File "/Users/madhurn/PycharmProjects/UMTSCellMap/UMTSCellMap/urls.py", line 24, in <module>
    url(r'^startnow/', include('startnow.urls', namespace="startnow")),
  File "/Library/Frameworks/Python.framework/Versions/2.7/lib/python2.7/site-packages/django/conf/urls/__init__.py", line 33, in include
    urlconf_module = import_module(urlconf_module)
  File "/opt/local/Library/Frameworks/Python.framework/Versions/2.7/lib/python2.7/importlib/__init__.py", line 37, in import_module
    __import__(name)
  File "/Users/madhurn/PycharmProjects/UMTSCellMap/startnow/urls.py", line 3, in <module>
    from views import empty
  File "/Users/madhurn/PycharmProjects/UMTSCellMap/startnow/views.py", line 4, in <module>
    from startnow import  Scheduler
  File "/Users/madhurn/PycharmProjects/UMTSCellMap/startnow/startnow.py", line 37
    def get_schedule(self)
                         ^
SyntaxError: invalid syntax
[15/Apr/2016 08:21:18] ERROR [django.request:256] Internal Server Error: /startnow/
Traceback (most recent call last):
  File "/Library/Frameworks/Python.framework/Versions/2.7/lib/python2.7/site-packages/django/core/handlers/base.py", line 119, in get_response
    resolver_match = resolver.resolve(request.path_info)
  File "/Library/Frameworks/Python.framework/Versions/2.7/lib/python2.7/site-packages/django/core/urlresolvers.py", line 365, in resolve
    for pattern in self.url_patterns:
  File "/Library/Frameworks/Python.framework/Versions/2.7/lib/python2.7/site-packages/django/core/urlresolvers.py", line 401, in url_patterns
    patterns = getattr(self.urlconf_module, "urlpatterns", self.urlconf_module)
  File "/Library/Frameworks/Python.framework/Versions/2.7/lib/python2.7/site-packages/django/core/urlresolvers.py", line 395, in urlconf_module
    self._urlconf_module = import_module(self.urlconf_name)
  File "/opt/local/Library/Frameworks/Python.framework/Versions/2.7/lib/python2.7/importlib/__init__.py", line 37, in import_module
    __import__(name)
  File "/Users/madhurn/PycharmProjects/UMTSCellMap/UMTSCellMap/urls.py", line 24, in <module>
    url(r'^startnow/', include('startnow.urls', namespace="startnow")),
  File "/Library/Frameworks/Python.framework/Versions/2.7/lib/python2.7/site-packages/django/conf/urls/__init__.py", line 33, in include
    urlconf_module = import_module(urlconf_module)
  File "/opt/local/Library/Frameworks/Python.framework/Versions/2.7/lib/python2.7/importlib/__init__.py", line 37, in import_module
    __import__(name)
  File "/Users/madhurn/PycharmProjects/UMTSCellMap/startnow/urls.py", line 3, in <module>
    from views import empty
  File "/Users/madhurn/PycharmProjects/UMTSCellMap/startnow/views.py", line 4, in <module>
    from startnow import  Scheduler
  File "/Users/madhurn/PycharmProjects/UMTSCellMap/startnow/startnow.py", line 37
    def get_schedule(self)
                         ^
SyntaxError: invalid syntax
[15/Apr/2016 08:21:18] ERROR [django.request:256] Internal Server Error: /startnow/
Traceback (most recent call last):
  File "/Library/Frameworks/Python.framework/Versions/2.7/lib/python2.7/site-packages/django/core/handlers/base.py", line 119, in get_response
    resolver_match = resolver.resolve(request.path_info)
  File "/Library/Frameworks/Python.framework/Versions/2.7/lib/python2.7/site-packages/django/core/urlresolvers.py", line 365, in resolve
    for pattern in self.url_patterns:
  File "/Library/Frameworks/Python.framework/Versions/2.7/lib/python2.7/site-packages/django/core/urlresolvers.py", line 401, in url_patterns
    patterns = getattr(self.urlconf_module, "urlpatterns", self.urlconf_module)
  File "/Library/Frameworks/Python.framework/Versions/2.7/lib/python2.7/site-packages/django/core/urlresolvers.py", line 395, in urlconf_module
    self._urlconf_module = import_module(self.urlconf_name)
  File "/opt/local/Library/Frameworks/Python.framework/Versions/2.7/lib/python2.7/importlib/__init__.py", line 37, in import_module
    __import__(name)
  File "/Users/madhurn/PycharmProjects/UMTSCellMap/UMTSCellMap/urls.py", line 24, in <module>
    url(r'^startnow/', include('startnow.urls', namespace="startnow")),
  File "/Library/Frameworks/Python.framework/Versions/2.7/lib/python2.7/site-packages/django/conf/urls/__init__.py", line 33, in include
    urlconf_module = import_module(urlconf_module)
  File "/opt/local/Library/Frameworks/Python.framework/Versions/2.7/lib/python2.7/importlib/__init__.py", line 37, in import_module
    __import__(name)
  File "/Users/madhurn/PycharmProjects/UMTSCellMap/startnow/urls.py", line 3, in <module>
    from views import empty
  File "/Users/madhurn/PycharmProjects/UMTSCellMap/startnow/views.py", line 4, in <module>
    from startnow import  Scheduler
  File "/Users/madhurn/PycharmProjects/UMTSCellMap/startnow/startnow.py", line 37
    def get_schedule(self)
                         ^
SyntaxError: invalid syntax
[15/Apr/2016 08:21:32] ERROR [django.request:256] Internal Server Error: /startnow/
Traceback (most recent call last):
  File "/Library/Frameworks/Python.framework/Versions/2.7/lib/python2.7/site-packages/django/core/handlers/base.py", line 132, in get_response
    response = wrapped_callback(request, *callback_args, **callback_kwargs)
  File "/Users/madhurn/PycharmProjects/UMTSCellMap/startnow/views.py", line 18, in index
    handlePostMethod(request)
  File "/Users/madhurn/PycharmProjects/UMTSCellMap/startnow/views.py", line 13, in handlePostMethod
    sched = Scheduler(orig_lat, orig_lng, dest_lat, dest_lng)
  File "/Users/madhurn/PycharmProjects/UMTSCellMap/startnow/startnow.py", line 7, in __init__
    self.orig_lat = orig_lat
NameError: global name 'self' is not defined
[15/Apr/2016 08:21:46] DEBUG [django.db.backends:89] (0.001) QUERY = "\n            SELECT name, type FROM sqlite_master\n            WHERE type in ('table', 'view') AND NOT name='sqlite_sequence'\n            ORDER BY name" - PARAMS = (); args=None
[15/Apr/2016 08:21:46] DEBUG [django.db.backends:89] (0.000) QUERY = u'SELECT "django_migrations"."app", "django_migrations"."name" FROM "django_migrations"' - PARAMS = (); args=()
[15/Apr/2016 08:21:49] ERROR [django.request:256] Internal Server Error: /startnow/
Traceback (most recent call last):
  File "/Library/Frameworks/Python.framework/Versions/2.7/lib/python2.7/site-packages/django/core/handlers/base.py", line 132, in get_response
    response = wrapped_callback(request, *callback_args, **callback_kwargs)
  File "/Users/madhurn/PycharmProjects/UMTSCellMap/startnow/views.py", line 18, in index
    handlePostMethod(request)
  File "/Users/madhurn/PycharmProjects/UMTSCellMap/startnow/views.py", line 14, in handlePostMethod
    return (sched.get_schedule())
  File "/Users/madhurn/PycharmProjects/UMTSCellMap/startnow/startnow.py", line 38, in get_schedule
    url = create_url()
NameError: global name 'create_url' is not defined
[15/Apr/2016 08:21:59] DEBUG [django.db.backends:89] (0.001) QUERY = "\n            SELECT name, type FROM sqlite_master\n            WHERE type in ('table', 'view') AND NOT name='sqlite_sequence'\n            ORDER BY name" - PARAMS = (); args=None
[15/Apr/2016 08:21:59] DEBUG [django.db.backends:89] (0.000) QUERY = u'SELECT "django_migrations"."app", "django_migrations"."name" FROM "django_migrations"' - PARAMS = (); args=()
[15/Apr/2016 08:22:02] ERROR [django.request:256] Internal Server Error: /startnow/
Traceback (most recent call last):
  File "/Library/Frameworks/Python.framework/Versions/2.7/lib/python2.7/site-packages/django/core/handlers/base.py", line 132, in get_response
    response = wrapped_callback(request, *callback_args, **callback_kwargs)
  File "/Users/madhurn/PycharmProjects/UMTSCellMap/startnow/views.py", line 18, in index
    handlePostMethod(request)
  File "/Users/madhurn/PycharmProjects/UMTSCellMap/startnow/views.py", line 14, in handlePostMethod
    return (sched.get_schedule())
  File "/Users/madhurn/PycharmProjects/UMTSCellMap/startnow/startnow.py", line 38, in get_schedule
    url = self.create_url()
  File "/Users/madhurn/PycharmProjects/UMTSCellMap/startnow/startnow.py", line 31, in create_url
    url_str = self.get_lat_long_url()
  File "/Users/madhurn/PycharmProjects/UMTSCellMap/startnow/startnow.py", line 15, in get_lat_long_url
    str = self.static_string.replace("ORIG_LAT_LONG", self.orig_lat+"%2C"+self.orig_lng)
TypeError: unsupported operand type(s) for +: 'NoneType' and 'str'
[15/Apr/2016 08:23:26] DEBUG [django.db.backends:89] (0.001) QUERY = "\n            SELECT name, type FROM sqlite_master\n            WHERE type in ('table', 'view') AND NOT name='sqlite_sequence'\n            ORDER BY name" - PARAMS = (); args=None
[15/Apr/2016 08:23:26] DEBUG [django.db.backends:89] (0.000) QUERY = u'SELECT "django_migrations"."app", "django_migrations"."name" FROM "django_migrations"' - PARAMS = (); args=()
[15/Apr/2016 08:23:30] ERROR [django.request:256] Internal Server Error: /startnow/
Traceback (most recent call last):
  File "/Library/Frameworks/Python.framework/Versions/2.7/lib/python2.7/site-packages/django/core/handlers/base.py", line 119, in get_response
    resolver_match = resolver.resolve(request.path_info)
  File "/Library/Frameworks/Python.framework/Versions/2.7/lib/python2.7/site-packages/django/core/urlresolvers.py", line 365, in resolve
    for pattern in self.url_patterns:
  File "/Library/Frameworks/Python.framework/Versions/2.7/lib/python2.7/site-packages/django/core/urlresolvers.py", line 401, in url_patterns
    patterns = getattr(self.urlconf_module, "urlpatterns", self.urlconf_module)
  File "/Library/Frameworks/Python.framework/Versions/2.7/lib/python2.7/site-packages/django/core/urlresolvers.py", line 395, in urlconf_module
    self._urlconf_module = import_module(self.urlconf_name)
  File "/opt/local/Library/Frameworks/Python.framework/Versions/2.7/lib/python2.7/importlib/__init__.py", line 37, in import_module
    __import__(name)
  File "/Users/madhurn/PycharmProjects/UMTSCellMap/UMTSCellMap/urls.py", line 24, in <module>
    url(r'^startnow/', include('startnow.urls', namespace="startnow")),
  File "/Library/Frameworks/Python.framework/Versions/2.7/lib/python2.7/site-packages/django/conf/urls/__init__.py", line 33, in include
    urlconf_module = import_module(urlconf_module)
  File "/opt/local/Library/Frameworks/Python.framework/Versions/2.7/lib/python2.7/importlib/__init__.py", line 37, in import_module
    __import__(name)
  File "/Users/madhurn/PycharmProjects/UMTSCellMap/startnow/urls.py", line 3, in <module>
    from views import empty
  File "/Users/madhurn/PycharmProjects/UMTSCellMap/startnow/views.py", line 4, in <module>
    from startnow import  Scheduler
  File "/Users/madhurn/PycharmProjects/UMTSCellMap/startnow/startnow.py", line 38
    if not self.orig_lat or
                          ^
SyntaxError: invalid syntax
[15/Apr/2016 08:23:50] ERROR [django.request:256] Internal Server Error: /startnow/
Traceback (most recent call last):
  File "/Library/Frameworks/Python.framework/Versions/2.7/lib/python2.7/site-packages/django/core/handlers/base.py", line 119, in get_response
    resolver_match = resolver.resolve(request.path_info)
  File "/Library/Frameworks/Python.framework/Versions/2.7/lib/python2.7/site-packages/django/core/urlresolvers.py", line 365, in resolve
    for pattern in self.url_patterns:
  File "/Library/Frameworks/Python.framework/Versions/2.7/lib/python2.7/site-packages/django/core/urlresolvers.py", line 401, in url_patterns
    patterns = getattr(self.urlconf_module, "urlpatterns", self.urlconf_module)
  File "/Library/Frameworks/Python.framework/Versions/2.7/lib/python2.7/site-packages/django/core/urlresolvers.py", line 395, in urlconf_module
    self._urlconf_module = import_module(self.urlconf_name)
  File "/opt/local/Library/Frameworks/Python.framework/Versions/2.7/lib/python2.7/importlib/__init__.py", line 37, in import_module
    __import__(name)
  File "/Users/madhurn/PycharmProjects/UMTSCellMap/UMTSCellMap/urls.py", line 24, in <module>
    url(r'^startnow/', include('startnow.urls', namespace="startnow")),
  File "/Library/Frameworks/Python.framework/Versions/2.7/lib/python2.7/site-packages/django/conf/urls/__init__.py", line 33, in include
    urlconf_module = import_module(urlconf_module)
  File "/opt/local/Library/Frameworks/Python.framework/Versions/2.7/lib/python2.7/importlib/__init__.py", line 37, in import_module
    __import__(name)
  File "/Users/madhurn/PycharmProjects/UMTSCellMap/startnow/urls.py", line 3, in <module>
    from views import empty
  File "/Users/madhurn/PycharmProjects/UMTSCellMap/startnow/views.py", line 4, in <module>
    from startnow import  Scheduler
  File "/Users/madhurn/PycharmProjects/UMTSCellMap/startnow/startnow.py", line 38
    if not self.orig_lat ||
                          ^
SyntaxError: invalid syntax
[15/Apr/2016 08:24:05] ERROR [django.request:256] Internal Server Error: /startnow/
Traceback (most recent call last):
  File "/Library/Frameworks/Python.framework/Versions/2.7/lib/python2.7/site-packages/django/core/handlers/base.py", line 119, in get_response
    resolver_match = resolver.resolve(request.path_info)
  File "/Library/Frameworks/Python.framework/Versions/2.7/lib/python2.7/site-packages/django/core/urlresolvers.py", line 365, in resolve
    for pattern in self.url_patterns:
  File "/Library/Frameworks/Python.framework/Versions/2.7/lib/python2.7/site-packages/django/core/urlresolvers.py", line 401, in url_patterns
    patterns = getattr(self.urlconf_module, "urlpatterns", self.urlconf_module)
  File "/Library/Frameworks/Python.framework/Versions/2.7/lib/python2.7/site-packages/django/core/urlresolvers.py", line 395, in urlconf_module
    self._urlconf_module = import_module(self.urlconf_name)
  File "/opt/local/Library/Frameworks/Python.framework/Versions/2.7/lib/python2.7/importlib/__init__.py", line 37, in import_module
    __import__(name)
  File "/Users/madhurn/PycharmProjects/UMTSCellMap/UMTSCellMap/urls.py", line 24, in <module>
    url(r'^startnow/', include('startnow.urls', namespace="startnow")),
  File "/Library/Frameworks/Python.framework/Versions/2.7/lib/python2.7/site-packages/django/conf/urls/__init__.py", line 33, in include
    urlconf_module = import_module(urlconf_module)
  File "/opt/local/Library/Frameworks/Python.framework/Versions/2.7/lib/python2.7/importlib/__init__.py", line 37, in import_module
    __import__(name)
  File "/Users/madhurn/PycharmProjects/UMTSCellMap/startnow/urls.py", line 3, in <module>
    from views import empty
  File "/Users/madhurn/PycharmProjects/UMTSCellMap/startnow/views.py", line 4, in <module>
    from startnow import  Scheduler
  File "/Users/madhurn/PycharmProjects/UMTSCellMap/startnow/startnow.py", line 38
    if !self.orig_lat ||
       ^
SyntaxError: invalid syntax
[15/Apr/2016 08:24:24] ERROR [django.request:256] Internal Server Error: /startnow/
Traceback (most recent call last):
  File "/Library/Frameworks/Python.framework/Versions/2.7/lib/python2.7/site-packages/django/core/handlers/base.py", line 119, in get_response
    resolver_match = resolver.resolve(request.path_info)
  File "/Library/Frameworks/Python.framework/Versions/2.7/lib/python2.7/site-packages/django/core/urlresolvers.py", line 365, in resolve
    for pattern in self.url_patterns:
  File "/Library/Frameworks/Python.framework/Versions/2.7/lib/python2.7/site-packages/django/core/urlresolvers.py", line 401, in url_patterns
    patterns = getattr(self.urlconf_module, "urlpatterns", self.urlconf_module)
  File "/Library/Frameworks/Python.framework/Versions/2.7/lib/python2.7/site-packages/django/core/urlresolvers.py", line 395, in urlconf_module
    self._urlconf_module = import_module(self.urlconf_name)
  File "/opt/local/Library/Frameworks/Python.framework/Versions/2.7/lib/python2.7/importlib/__init__.py", line 37, in import_module
    __import__(name)
  File "/Users/madhurn/PycharmProjects/UMTSCellMap/UMTSCellMap/urls.py", line 24, in <module>
    url(r'^startnow/', include('startnow.urls', namespace="startnow")),
  File "/Library/Frameworks/Python.framework/Versions/2.7/lib/python2.7/site-packages/django/conf/urls/__init__.py", line 33, in include
    urlconf_module = import_module(urlconf_module)
  File "/opt/local/Library/Frameworks/Python.framework/Versions/2.7/lib/python2.7/importlib/__init__.py", line 37, in import_module
    __import__(name)
  File "/Users/madhurn/PycharmProjects/UMTSCellMap/startnow/urls.py", line 3, in <module>
    from views import empty
  File "/Users/madhurn/PycharmProjects/UMTSCellMap/startnow/views.py", line 4, in <module>
    from startnow import  Scheduler
  File "/Users/madhurn/PycharmProjects/UMTSCellMap/startnow/startnow.py", line 38
    if !self.orig_lat || !self.orig_lng || !self.dest_lat || !self.dest_lng:
       ^
SyntaxError: invalid syntax
[15/Apr/2016 08:25:50] ERROR [django.request:256] Internal Server Error: /startnow/
Traceback (most recent call last):
  File "/Library/Frameworks/Python.framework/Versions/2.7/lib/python2.7/site-packages/django/core/handlers/base.py", line 132, in get_response
    response = wrapped_callback(request, *callback_args, **callback_kwargs)
  File "/Users/madhurn/PycharmProjects/UMTSCellMap/startnow/views.py", line 18, in index
    handlePostMethod(request)
  File "/Users/madhurn/PycharmProjects/UMTSCellMap/startnow/views.py", line 14, in handlePostMethod
    return (sched.get_schedule())
  File "/Users/madhurn/PycharmProjects/UMTSCellMap/startnow/startnow.py", line 44, in get_schedule
    if not validate_data:
NameError: global name 'validate_data' is not defined
[15/Apr/2016 08:25:55] DEBUG [django.db.backends:89] (0.001) QUERY = "\n            SELECT name, type FROM sqlite_master\n            WHERE type in ('table', 'view') AND NOT name='sqlite_sequence'\n            ORDER BY name" - PARAMS = (); args=None
[15/Apr/2016 08:25:55] DEBUG [django.db.backends:89] (0.000) QUERY = u'SELECT "django_migrations"."app", "django_migrations"."name" FROM "django_migrations"' - PARAMS = (); args=()
[15/Apr/2016 08:25:58] ERROR [django.request:256] Internal Server Error: /startnow/
Traceback (most recent call last):
  File "/Library/Frameworks/Python.framework/Versions/2.7/lib/python2.7/site-packages/django/core/handlers/base.py", line 132, in get_response
    response = wrapped_callback(request, *callback_args, **callback_kwargs)
  File "/Users/madhurn/PycharmProjects/UMTSCellMap/startnow/views.py", line 18, in index
    handlePostMethod(request)
  File "/Users/madhurn/PycharmProjects/UMTSCellMap/startnow/views.py", line 14, in handlePostMethod
    return (sched.get_schedule())
  File "/Users/madhurn/PycharmProjects/UMTSCellMap/startnow/startnow.py", line 46, in get_schedule
    url = self.create_url()
  File "/Users/madhurn/PycharmProjects/UMTSCellMap/startnow/startnow.py", line 31, in create_url
    url_str = self.get_lat_long_url()
  File "/Users/madhurn/PycharmProjects/UMTSCellMap/startnow/startnow.py", line 15, in get_lat_long_url
    str = self.static_string.replace("ORIG_LAT_LONG", self.orig_lat+"%2C"+self.orig_lng)
TypeError: unsupported operand type(s) for +: 'NoneType' and 'str'
[15/Apr/2016 08:26:34] ERROR [django.request:256] Internal Server Error: /startnow/
Traceback (most recent call last):
  File "/Library/Frameworks/Python.framework/Versions/2.7/lib/python2.7/site-packages/django/core/handlers/base.py", line 132, in get_response
    response = wrapped_callback(request, *callback_args, **callback_kwargs)
  File "/Users/madhurn/PycharmProjects/UMTSCellMap/startnow/views.py", line 18, in index
    handlePostMethod(request)
  File "/Users/madhurn/PycharmProjects/UMTSCellMap/startnow/views.py", line 14, in handlePostMethod
    return (sched.get_schedule())
  File "/Users/madhurn/PycharmProjects/UMTSCellMap/startnow/startnow.py", line 46, in get_schedule
    url = self.create_url()
  File "/Users/madhurn/PycharmProjects/UMTSCellMap/startnow/startnow.py", line 31, in create_url
    url_str = self.get_lat_long_url()
  File "/Users/madhurn/PycharmProjects/UMTSCellMap/startnow/startnow.py", line 15, in get_lat_long_url
    str = self.static_string.replace("ORIG_LAT_LONG", self.orig_lat+"%2C"+self.orig_lng)
TypeError: unsupported operand type(s) for +: 'NoneType' and 'str'
[15/Apr/2016 08:41:43] ERROR [django.request:256] Internal Server Error: /startnow/
Traceback (most recent call last):
  File "/Library/Frameworks/Python.framework/Versions/2.7/lib/python2.7/site-packages/django/core/handlers/base.py", line 132, in get_response
    response = wrapped_callback(request, *callback_args, **callback_kwargs)
  File "/Users/madhurn/PycharmProjects/UMTSCellMap/startnow/views.py", line 18, in index
    handlePostMethod(request)
  File "/Users/madhurn/PycharmProjects/UMTSCellMap/startnow/views.py", line 14, in handlePostMethod
    return (sched.get_schedule())
  File "/Users/madhurn/PycharmProjects/UMTSCellMap/startnow/startnow.py", line 46, in get_schedule
    url = self.create_url()
  File "/Users/madhurn/PycharmProjects/UMTSCellMap/startnow/startnow.py", line 31, in create_url
    url_str = self.get_lat_long_url()
  File "/Users/madhurn/PycharmProjects/UMTSCellMap/startnow/startnow.py", line 15, in get_lat_long_url
    str = self.static_string.replace("ORIG_LAT_LONG", self.orig_lat+"%2C"+self.orig_lng)
TypeError: unsupported operand type(s) for +: 'NoneType' and 'str'
[15/Apr/2016 08:44:07] ERROR [django.request:256] Internal Server Error: /startnow/
Traceback (most recent call last):
  File "/Library/Frameworks/Python.framework/Versions/2.7/lib/python2.7/site-packages/django/core/handlers/base.py", line 132, in get_response
    response = wrapped_callback(request, *callback_args, **callback_kwargs)
  File "/Users/madhurn/PycharmProjects/UMTSCellMap/startnow/views.py", line 18, in index
    handlePostMethod(request)
  File "/Users/madhurn/PycharmProjects/UMTSCellMap/startnow/views.py", line 14, in handlePostMethod
    return (sched.get_schedule())
  File "/Users/madhurn/PycharmProjects/UMTSCellMap/startnow/startnow.py", line 46, in get_schedule
    url = self.create_url()
  File "/Users/madhurn/PycharmProjects/UMTSCellMap/startnow/startnow.py", line 31, in create_url
    url_str = self.get_lat_long_url()
  File "/Users/madhurn/PycharmProjects/UMTSCellMap/startnow/startnow.py", line 15, in get_lat_long_url
    str = self.static_string.replace("ORIG_LAT_LONG", self.orig_lat+"%2C"+self.orig_lng)
TypeError: unsupported operand type(s) for +: 'NoneType' and 'str'
[15/Apr/2016 08:45:10] DEBUG [django.db.backends:89] (0.001) QUERY = "\n            SELECT name, type FROM sqlite_master\n            WHERE type in ('table', 'view') AND NOT name='sqlite_sequence'\n            ORDER BY name" - PARAMS = (); args=None
[15/Apr/2016 08:45:10] DEBUG [django.db.backends:89] (0.000) QUERY = u'SELECT "django_migrations"."app", "django_migrations"."name" FROM "django_migrations"' - PARAMS = (); args=()
[15/Apr/2016 08:45:38] ERROR [django.request:256] Internal Server Error: /startnow/
Traceback (most recent call last):
  File "/Library/Frameworks/Python.framework/Versions/2.7/lib/python2.7/site-packages/django/core/handlers/base.py", line 132, in get_response
    response = wrapped_callback(request, *callback_args, **callback_kwargs)
  File "/Users/madhurn/PycharmProjects/UMTSCellMap/startnow/views.py", line 18, in index
    handlePostMethod(request)
  File "/Users/madhurn/PycharmProjects/UMTSCellMap/startnow/views.py", line 14, in handlePostMethod
    return (sched.get_schedule())
  File "/Users/madhurn/PycharmProjects/UMTSCellMap/startnow/startnow.py", line 46, in get_schedule
    url = self.create_url()
  File "/Users/madhurn/PycharmProjects/UMTSCellMap/startnow/startnow.py", line 31, in create_url
    url_str = self.get_lat_long_url()
  File "/Users/madhurn/PycharmProjects/UMTSCellMap/startnow/startnow.py", line 15, in get_lat_long_url
    str = self.static_string.replace("ORIG_LAT_LONG", self.orig_lat+"%2C"+self.orig_lng)
TypeError: unsupported operand type(s) for +: 'NoneType' and 'str'
[15/Apr/2016 08:46:41] ERROR [django.request:256] Internal Server Error: /startnow/
Traceback (most recent call last):
  File "/Library/Frameworks/Python.framework/Versions/2.7/lib/python2.7/site-packages/django/core/handlers/base.py", line 132, in get_response
    response = wrapped_callback(request, *callback_args, **callback_kwargs)
  File "/Users/madhurn/PycharmProjects/UMTSCellMap/startnow/views.py", line 18, in index
    handlePostMethod(request)
  File "/Users/madhurn/PycharmProjects/UMTSCellMap/startnow/views.py", line 14, in handlePostMethod
    return (sched.get_schedule())
  File "/Users/madhurn/PycharmProjects/UMTSCellMap/startnow/startnow.py", line 46, in get_schedule
    url = self.create_url()
  File "/Users/madhurn/PycharmProjects/UMTSCellMap/startnow/startnow.py", line 31, in create_url
    url_str = self.get_lat_long_url()
  File "/Users/madhurn/PycharmProjects/UMTSCellMap/startnow/startnow.py", line 15, in get_lat_long_url
    str = self.static_string.replace("ORIG_LAT_LONG", self.orig_lat+"%2C"+self.orig_lng)
TypeError: unsupported operand type(s) for +: 'NoneType' and 'str'
[15/Apr/2016 08:46:51] ERROR [django.request:256] Internal Server Error: /startnow/
Traceback (most recent call last):
  File "/Library/Frameworks/Python.framework/Versions/2.7/lib/python2.7/site-packages/django/core/handlers/base.py", line 132, in get_response
    response = wrapped_callback(request, *callback_args, **callback_kwargs)
  File "/Users/madhurn/PycharmProjects/UMTSCellMap/startnow/views.py", line 18, in index
    handlePostMethod(request)
  File "/Users/madhurn/PycharmProjects/UMTSCellMap/startnow/views.py", line 14, in handlePostMethod
    return (sched.get_schedule())
  File "/Users/madhurn/PycharmProjects/UMTSCellMap/startnow/startnow.py", line 46, in get_schedule
    url = self.create_url()
  File "/Users/madhurn/PycharmProjects/UMTSCellMap/startnow/startnow.py", line 31, in create_url
    url_str = self.get_lat_long_url()
  File "/Users/madhurn/PycharmProjects/UMTSCellMap/startnow/startnow.py", line 15, in get_lat_long_url
    str = self.static_string.replace("ORIG_LAT_LONG", self.orig_lat+"%2C"+self.orig_lng)
TypeError: unsupported operand type(s) for +: 'NoneType' and 'str'
[15/Apr/2016 08:46:52] ERROR [django.request:256] Internal Server Error: /startnow/
Traceback (most recent call last):
  File "/Library/Frameworks/Python.framework/Versions/2.7/lib/python2.7/site-packages/django/core/handlers/base.py", line 132, in get_response
    response = wrapped_callback(request, *callback_args, **callback_kwargs)
  File "/Users/madhurn/PycharmProjects/UMTSCellMap/startnow/views.py", line 18, in index
    handlePostMethod(request)
  File "/Users/madhurn/PycharmProjects/UMTSCellMap/startnow/views.py", line 14, in handlePostMethod
    return (sched.get_schedule())
  File "/Users/madhurn/PycharmProjects/UMTSCellMap/startnow/startnow.py", line 46, in get_schedule
    url = self.create_url()
  File "/Users/madhurn/PycharmProjects/UMTSCellMap/startnow/startnow.py", line 31, in create_url
    url_str = self.get_lat_long_url()
  File "/Users/madhurn/PycharmProjects/UMTSCellMap/startnow/startnow.py", line 15, in get_lat_long_url
    str = self.static_string.replace("ORIG_LAT_LONG", self.orig_lat+"%2C"+self.orig_lng)
TypeError: unsupported operand type(s) for +: 'NoneType' and 'str'
[15/Apr/2016 08:46:52] ERROR [django.request:256] Internal Server Error: /startnow/
Traceback (most recent call last):
  File "/Library/Frameworks/Python.framework/Versions/2.7/lib/python2.7/site-packages/django/core/handlers/base.py", line 132, in get_response
    response = wrapped_callback(request, *callback_args, **callback_kwargs)
  File "/Users/madhurn/PycharmProjects/UMTSCellMap/startnow/views.py", line 18, in index
    handlePostMethod(request)
  File "/Users/madhurn/PycharmProjects/UMTSCellMap/startnow/views.py", line 14, in handlePostMethod
    return (sched.get_schedule())
  File "/Users/madhurn/PycharmProjects/UMTSCellMap/startnow/startnow.py", line 46, in get_schedule
    url = self.create_url()
  File "/Users/madhurn/PycharmProjects/UMTSCellMap/startnow/startnow.py", line 31, in create_url
    url_str = self.get_lat_long_url()
  File "/Users/madhurn/PycharmProjects/UMTSCellMap/startnow/startnow.py", line 15, in get_lat_long_url
    str = self.static_string.replace("ORIG_LAT_LONG", self.orig_lat+"%2C"+self.orig_lng)
TypeError: unsupported operand type(s) for +: 'NoneType' and 'str'
[15/Apr/2016 08:46:52] ERROR [django.request:256] Internal Server Error: /startnow/
Traceback (most recent call last):
  File "/Library/Frameworks/Python.framework/Versions/2.7/lib/python2.7/site-packages/django/core/handlers/base.py", line 132, in get_response
    response = wrapped_callback(request, *callback_args, **callback_kwargs)
  File "/Users/madhurn/PycharmProjects/UMTSCellMap/startnow/views.py", line 18, in index
    handlePostMethod(request)
  File "/Users/madhurn/PycharmProjects/UMTSCellMap/startnow/views.py", line 14, in handlePostMethod
    return (sched.get_schedule())
  File "/Users/madhurn/PycharmProjects/UMTSCellMap/startnow/startnow.py", line 46, in get_schedule
    url = self.create_url()
  File "/Users/madhurn/PycharmProjects/UMTSCellMap/startnow/startnow.py", line 31, in create_url
    url_str = self.get_lat_long_url()
  File "/Users/madhurn/PycharmProjects/UMTSCellMap/startnow/startnow.py", line 15, in get_lat_long_url
    str = self.static_string.replace("ORIG_LAT_LONG", self.orig_lat+"%2C"+self.orig_lng)
TypeError: unsupported operand type(s) for +: 'NoneType' and 'str'
[15/Apr/2016 08:46:56] ERROR [django.request:256] Internal Server Error: /startnow/
Traceback (most recent call last):
  File "/Library/Frameworks/Python.framework/Versions/2.7/lib/python2.7/site-packages/django/core/handlers/base.py", line 132, in get_response
    response = wrapped_callback(request, *callback_args, **callback_kwargs)
  File "/Users/madhurn/PycharmProjects/UMTSCellMap/startnow/views.py", line 18, in index
    handlePostMethod(request)
  File "/Users/madhurn/PycharmProjects/UMTSCellMap/startnow/views.py", line 14, in handlePostMethod
    return (sched.get_schedule())
  File "/Users/madhurn/PycharmProjects/UMTSCellMap/startnow/startnow.py", line 46, in get_schedule
    url = self.create_url()
  File "/Users/madhurn/PycharmProjects/UMTSCellMap/startnow/startnow.py", line 31, in create_url
    url_str = self.get_lat_long_url()
  File "/Users/madhurn/PycharmProjects/UMTSCellMap/startnow/startnow.py", line 15, in get_lat_long_url
    str = self.static_string.replace("ORIG_LAT_LONG", self.orig_lat+"%2C"+self.orig_lng)
TypeError: unsupported operand type(s) for +: 'NoneType' and 'str'
[15/Apr/2016 08:47:12] ERROR [django.request:256] Internal Server Error: /startnow/
Traceback (most recent call last):
  File "/Library/Frameworks/Python.framework/Versions/2.7/lib/python2.7/site-packages/django/core/handlers/base.py", line 132, in get_response
    response = wrapped_callback(request, *callback_args, **callback_kwargs)
  File "/Users/madhurn/PycharmProjects/UMTSCellMap/startnow/views.py", line 18, in index
    handlePostMethod(request)
  File "/Users/madhurn/PycharmProjects/UMTSCellMap/startnow/views.py", line 14, in handlePostMethod
    return (sched.get_schedule())
  File "/Users/madhurn/PycharmProjects/UMTSCellMap/startnow/startnow.py", line 46, in get_schedule
    url = self.create_url()
  File "/Users/madhurn/PycharmProjects/UMTSCellMap/startnow/startnow.py", line 32, in create_url
    logger.info("URL Str with Lat Long info {}".format(url_str))
NameError: global name 'logger' is not defined
[15/Apr/2016 08:47:45] DEBUG [django.db.backends:89] (0.001) QUERY = "\n            SELECT name, type FROM sqlite_master\n            WHERE type in ('table', 'view') AND NOT name='sqlite_sequence'\n            ORDER BY name" - PARAMS = (); args=None
[15/Apr/2016 08:47:45] DEBUG [django.db.backends:89] (0.000) QUERY = u'SELECT "django_migrations"."app", "django_migrations"."name" FROM "django_migrations"' - PARAMS = (); args=()
[15/Apr/2016 08:47:47] ERROR [django.request:256] Internal Server Error: /startnow/
Traceback (most recent call last):
  File "/Library/Frameworks/Python.framework/Versions/2.7/lib/python2.7/site-packages/django/core/handlers/base.py", line 119, in get_response
    resolver_match = resolver.resolve(request.path_info)
  File "/Library/Frameworks/Python.framework/Versions/2.7/lib/python2.7/site-packages/django/core/urlresolvers.py", line 365, in resolve
    for pattern in self.url_patterns:
  File "/Library/Frameworks/Python.framework/Versions/2.7/lib/python2.7/site-packages/django/core/urlresolvers.py", line 401, in url_patterns
    patterns = getattr(self.urlconf_module, "urlpatterns", self.urlconf_module)
  File "/Library/Frameworks/Python.framework/Versions/2.7/lib/python2.7/site-packages/django/core/urlresolvers.py", line 395, in urlconf_module
    self._urlconf_module = import_module(self.urlconf_name)
  File "/opt/local/Library/Frameworks/Python.framework/Versions/2.7/lib/python2.7/importlib/__init__.py", line 37, in import_module
    __import__(name)
  File "/Users/madhurn/PycharmProjects/UMTSCellMap/UMTSCellMap/urls.py", line 24, in <module>
    url(r'^startnow/', include('startnow.urls', namespace="startnow")),
  File "/Library/Frameworks/Python.framework/Versions/2.7/lib/python2.7/site-packages/django/conf/urls/__init__.py", line 33, in include
    urlconf_module = import_module(urlconf_module)
  File "/opt/local/Library/Frameworks/Python.framework/Versions/2.7/lib/python2.7/importlib/__init__.py", line 37, in import_module
    __import__(name)
  File "/Users/madhurn/PycharmProjects/UMTSCellMap/startnow/urls.py", line 3, in <module>
    from views import empty
  File "/Users/madhurn/PycharmProjects/UMTSCellMap/startnow/views.py", line 4, in <module>
    from startnow import  Scheduler
  File "/Users/madhurn/PycharmProjects/UMTSCellMap/startnow/startnow.py", line 2, in <module>
    from logging import logger
ImportError: cannot import name logger
[15/Apr/2016 08:48:19] ERROR [django.request:256] Internal Server Error: /startnow/
Traceback (most recent call last):
  File "/Library/Frameworks/Python.framework/Versions/2.7/lib/python2.7/site-packages/django/core/handlers/base.py", line 119, in get_response
    resolver_match = resolver.resolve(request.path_info)
  File "/Library/Frameworks/Python.framework/Versions/2.7/lib/python2.7/site-packages/django/core/urlresolvers.py", line 365, in resolve
    for pattern in self.url_patterns:
  File "/Library/Frameworks/Python.framework/Versions/2.7/lib/python2.7/site-packages/django/core/urlresolvers.py", line 401, in url_patterns
    patterns = getattr(self.urlconf_module, "urlpatterns", self.urlconf_module)
  File "/Library/Frameworks/Python.framework/Versions/2.7/lib/python2.7/site-packages/django/core/urlresolvers.py", line 395, in urlconf_module
    self._urlconf_module = import_module(self.urlconf_name)
  File "/opt/local/Library/Frameworks/Python.framework/Versions/2.7/lib/python2.7/importlib/__init__.py", line 37, in import_module
    __import__(name)
  File "/Users/madhurn/PycharmProjects/UMTSCellMap/UMTSCellMap/urls.py", line 24, in <module>
    url(r'^startnow/', include('startnow.urls', namespace="startnow")),
  File "/Library/Frameworks/Python.framework/Versions/2.7/lib/python2.7/site-packages/django/conf/urls/__init__.py", line 33, in include
    urlconf_module = import_module(urlconf_module)
  File "/opt/local/Library/Frameworks/Python.framework/Versions/2.7/lib/python2.7/importlib/__init__.py", line 37, in import_module
    __import__(name)
  File "/Users/madhurn/PycharmProjects/UMTSCellMap/startnow/urls.py", line 3, in <module>
    from views import empty
  File "/Users/madhurn/PycharmProjects/UMTSCellMap/startnow/views.py", line 4, in <module>
    from startnow import  Scheduler
  File "/Users/madhurn/PycharmProjects/UMTSCellMap/startnow/startnow.py", line 2, in <module>
    from logging import logger
ImportError: cannot import name logger
[15/Apr/2016 09:58:34] DEBUG [django.db.backends:89] (0.002) QUERY = "\n            SELECT name, type FROM sqlite_master\n            WHERE type in ('table', 'view') AND NOT name='sqlite_sequence'\n            ORDER BY name" - PARAMS = (); args=None
[15/Apr/2016 09:58:34] DEBUG [django.db.backends:89] (0.000) QUERY = u'SELECT "django_migrations"."app", "django_migrations"."name" FROM "django_migrations"' - PARAMS = (); args=()
[15/Apr/2016 09:58:37] ERROR [django.request:256] Internal Server Error: /startnow/
Traceback (most recent call last):
  File "/Library/Frameworks/Python.framework/Versions/2.7/lib/python2.7/site-packages/django/core/handlers/base.py", line 132, in get_response
    response = wrapped_callback(request, *callback_args, **callback_kwargs)
  File "/Users/madhurn/PycharmProjects/UMTSCellMap/startnow/views.py", line 18, in index
    handlePostMethod(request)
  File "/Users/madhurn/PycharmProjects/UMTSCellMap/startnow/views.py", line 14, in handlePostMethod
    return (sched.get_schedule())
  File "/Users/madhurn/PycharmProjects/UMTSCellMap/startnow/startnow.py", line 48, in get_schedule
    url = self.create_url()
  File "/Users/madhurn/PycharmProjects/UMTSCellMap/startnow/startnow.py", line 36, in create_url
    url_str = update_time_in_url(url_str, curr_time)
NameError: global name 'update_time_in_url' is not defined
[15/Apr/2016 09:58:52] DEBUG [django.db.backends:89] (0.002) QUERY = "\n            SELECT name, type FROM sqlite_master\n            WHERE type in ('table', 'view') AND NOT name='sqlite_sequence'\n            ORDER BY name" - PARAMS = (); args=None
[15/Apr/2016 09:58:52] DEBUG [django.db.backends:89] (0.000) QUERY = u'SELECT "django_migrations"."app", "django_migrations"."name" FROM "django_migrations"' - PARAMS = (); args=()
[15/Apr/2016 09:59:08] ERROR [django.request:256] Internal Server Error: /startnow/
Traceback (most recent call last):
  File "/Library/Frameworks/Python.framework/Versions/2.7/lib/python2.7/site-packages/django/core/handlers/base.py", line 132, in get_response
    response = wrapped_callback(request, *callback_args, **callback_kwargs)
  File "/Users/madhurn/PycharmProjects/UMTSCellMap/startnow/views.py", line 18, in index
    handlePostMethod(request)
  File "/Users/madhurn/PycharmProjects/UMTSCellMap/startnow/views.py", line 14, in handlePostMethod
    return (sched.get_schedule())
  File "/Users/madhurn/PycharmProjects/UMTSCellMap/startnow/startnow.py", line 48, in get_schedule
    url = self.create_url()
  File "/Users/madhurn/PycharmProjects/UMTSCellMap/startnow/startnow.py", line 36, in create_url
    url_str = self.update_time_in_url(url_str, curr_time)
  File "/Users/madhurn/PycharmProjects/UMTSCellMap/startnow/startnow.py", line 30, in update_time_in_url
    str.replace("DEPARTAT", time)
TypeError: coercing to Unicode: need string or buffer, int found
[15/Apr/2016 10:00:08] DEBUG [django.db.backends:89] (0.001) QUERY = "\n            SELECT name, type FROM sqlite_master\n            WHERE type in ('table', 'view') AND NOT name='sqlite_sequence'\n            ORDER BY name" - PARAMS = (); args=None
[15/Apr/2016 10:00:08] DEBUG [django.db.backends:89] (0.000) QUERY = u'SELECT "django_migrations"."app", "django_migrations"."name" FROM "django_migrations"' - PARAMS = (); args=()
[15/Apr/2016 10:03:19] ERROR [django.request:256] Internal Server Error: /startnow/
Traceback (most recent call last):
  File "/Library/Frameworks/Python.framework/Versions/2.7/lib/python2.7/site-packages/django/core/handlers/base.py", line 132, in get_response
    response = wrapped_callback(request, *callback_args, **callback_kwargs)
  File "/Users/madhurn/PycharmProjects/UMTSCellMap/startnow/views.py", line 18, in index
    handlePostMethod(request)
  File "/Users/madhurn/PycharmProjects/UMTSCellMap/startnow/views.py", line 14, in handlePostMethod
    return (sched.get_schedule())
  File "/Users/madhurn/PycharmProjects/UMTSCellMap/startnow/startnow.py", line 48, in get_schedule
    url = self.create_url()
  File "/Users/madhurn/PycharmProjects/UMTSCellMap/startnow/startnow.py", line 36, in create_url
    url_str = self.update_time_in_url(url_str, curr_time)
  File "/Users/madhurn/PycharmProjects/UMTSCellMap/startnow/startnow.py", line 30, in update_time_in_url
    str.replace("DEPARTAT", time)
TypeError: coercing to Unicode: need string or buffer, int found
[15/Apr/2016 10:03:44] DEBUG [django.db.backends:89] (0.002) QUERY = "\n            SELECT name, type FROM sqlite_master\n            WHERE type in ('table', 'view') AND NOT name='sqlite_sequence'\n            ORDER BY name" - PARAMS = (); args=None
[15/Apr/2016 10:03:44] DEBUG [django.db.backends:89] (0.000) QUERY = u'SELECT "django_migrations"."app", "django_migrations"."name" FROM "django_migrations"' - PARAMS = (); args=()
[15/Apr/2016 10:03:49] ERROR [django.request:256] Internal Server Error: /startnow/
Traceback (most recent call last):
  File "/Library/Frameworks/Python.framework/Versions/2.7/lib/python2.7/site-packages/django/core/handlers/base.py", line 132, in get_response
    response = wrapped_callback(request, *callback_args, **callback_kwargs)
  File "/Users/madhurn/PycharmProjects/UMTSCellMap/startnow/views.py", line 18, in index
    handlePostMethod(request)
  File "/Users/madhurn/PycharmProjects/UMTSCellMap/startnow/views.py", line 14, in handlePostMethod
    return (sched.get_schedule())
  File "/Users/madhurn/PycharmProjects/UMTSCellMap/startnow/startnow.py", line 48, in get_schedule
    url = self.create_url()
  File "/Users/madhurn/PycharmProjects/UMTSCellMap/startnow/startnow.py", line 36, in create_url
    url_str = self.update_time_in_url(url_str, curr_time)
  File "/Users/madhurn/PycharmProjects/UMTSCellMap/startnow/startnow.py", line 30, in update_time_in_url
    str.replace("DEPARTAT", str(time))
TypeError: 'unicode' object is not callable
[15/Apr/2016 10:05:15] DEBUG [django.db.backends:89] (0.002) QUERY = "\n            SELECT name, type FROM sqlite_master\n            WHERE type in ('table', 'view') AND NOT name='sqlite_sequence'\n            ORDER BY name" - PARAMS = (); args=None
[15/Apr/2016 10:05:15] DEBUG [django.db.backends:89] (0.000) QUERY = u'SELECT "django_migrations"."app", "django_migrations"."name" FROM "django_migrations"' - PARAMS = (); args=()
[15/Apr/2016 10:05:39] ERROR [django.request:256] Internal Server Error: /startnow/
Traceback (most recent call last):
  File "/Library/Frameworks/Python.framework/Versions/2.7/lib/python2.7/site-packages/django/core/handlers/base.py", line 132, in get_response
    response = wrapped_callback(request, *callback_args, **callback_kwargs)
  File "/Users/madhurn/PycharmProjects/UMTSCellMap/startnow/views.py", line 18, in index
    handlePostMethod(request)
  File "/Users/madhurn/PycharmProjects/UMTSCellMap/startnow/views.py", line 14, in handlePostMethod
    return (sched.get_schedule())
  File "/Users/madhurn/PycharmProjects/UMTSCellMap/startnow/startnow.py", line 49, in get_schedule
    url = self.create_url()
  File "/Users/madhurn/PycharmProjects/UMTSCellMap/startnow/startnow.py", line 37, in create_url
    url_str = self.update_time_in_url(url_str, curr_time)
  File "/Users/madhurn/PycharmProjects/UMTSCellMap/startnow/startnow.py", line 30, in update_time_in_url
    str=str.replace("DEPARTAT", str(time))
TypeError: 'unicode' object is not callable
[15/Apr/2016 10:05:47] DEBUG [django.db.backends:89] (0.001) QUERY = "\n            SELECT name, type FROM sqlite_master\n            WHERE type in ('table', 'view') AND NOT name='sqlite_sequence'\n            ORDER BY name" - PARAMS = (); args=None
[15/Apr/2016 10:05:47] DEBUG [django.db.backends:89] (0.000) QUERY = u'SELECT "django_migrations"."app", "django_migrations"."name" FROM "django_migrations"' - PARAMS = (); args=()
[15/Apr/2016 10:05:50] ERROR [django.request:256] Internal Server Error: /startnow/
Traceback (most recent call last):
  File "/Library/Frameworks/Python.framework/Versions/2.7/lib/python2.7/site-packages/django/core/handlers/base.py", line 132, in get_response
    response = wrapped_callback(request, *callback_args, **callback_kwargs)
  File "/Users/madhurn/PycharmProjects/UMTSCellMap/startnow/views.py", line 18, in index
    handlePostMethod(request)
  File "/Users/madhurn/PycharmProjects/UMTSCellMap/startnow/views.py", line 14, in handlePostMethod
    return (sched.get_schedule())
  File "/Users/madhurn/PycharmProjects/UMTSCellMap/startnow/startnow.py", line 49, in get_schedule
    url = self.create_url()
  File "/Users/madhurn/PycharmProjects/UMTSCellMap/startnow/startnow.py", line 37, in create_url
    url_str = self.update_time_in_url(url_str, curr_time)
  File "/Users/madhurn/PycharmProjects/UMTSCellMap/startnow/startnow.py", line 30, in update_time_in_url
    str=str.replace("DEPARTAT", str(time))
TypeError: 'unicode' object is not callable
[15/Apr/2016 10:06:24] DEBUG [django.db.backends:89] (0.001) QUERY = "\n            SELECT name, type FROM sqlite_master\n            WHERE type in ('table', 'view') AND NOT name='sqlite_sequence'\n            ORDER BY name" - PARAMS = (); args=None
[15/Apr/2016 10:06:24] DEBUG [django.db.backends:89] (0.000) QUERY = u'SELECT "django_migrations"."app", "django_migrations"."name" FROM "django_migrations"' - PARAMS = (); args=()
[15/Apr/2016 10:06:29] ERROR [django.request:256] Internal Server Error: /startnow/
Traceback (most recent call last):
  File "/Library/Frameworks/Python.framework/Versions/2.7/lib/python2.7/site-packages/django/core/handlers/base.py", line 132, in get_response
    response = wrapped_callback(request, *callback_args, **callback_kwargs)
  File "/Users/madhurn/PycharmProjects/UMTSCellMap/startnow/views.py", line 18, in index
    handlePostMethod(request)
  File "/Users/madhurn/PycharmProjects/UMTSCellMap/startnow/views.py", line 14, in handlePostMethod
    return (sched.get_schedule())
  File "/Users/madhurn/PycharmProjects/UMTSCellMap/startnow/startnow.py", line 50, in get_schedule
    url = self.create_url()
  File "/Users/madhurn/PycharmProjects/UMTSCellMap/startnow/startnow.py", line 38, in create_url
    url_str = self.update_time_in_url(url_str, curr_time)
  File "/Users/madhurn/PycharmProjects/UMTSCellMap/startnow/startnow.py", line 31, in update_time_in_url
    str=str.replace("DEPARTAT", str(time))
TypeError: 'unicode' object is not callable
[15/Apr/2016 10:07:13] DEBUG [django.db.backends:89] (0.001) QUERY = "\n            SELECT name, type FROM sqlite_master\n            WHERE type in ('table', 'view') AND NOT name='sqlite_sequence'\n            ORDER BY name" - PARAMS = (); args=None
[15/Apr/2016 10:07:13] DEBUG [django.db.backends:89] (0.000) QUERY = u'SELECT "django_migrations"."app", "django_migrations"."name" FROM "django_migrations"' - PARAMS = (); args=()
[15/Apr/2016 10:07:26] ERROR [django.request:256] Internal Server Error: /startnow/
Traceback (most recent call last):
  File "/Library/Frameworks/Python.framework/Versions/2.7/lib/python2.7/site-packages/django/core/handlers/base.py", line 151, in get_response
    % (callback.__module__, view_name))
ValueError: The view startnow.views.index didn't return an HttpResponse object. It returned None instead.
[15/Apr/2016 10:08:02] DEBUG [django.db.backends:89] (0.002) QUERY = "\n            SELECT name, type FROM sqlite_master\n            WHERE type in ('table', 'view') AND NOT name='sqlite_sequence'\n            ORDER BY name" - PARAMS = (); args=None
[15/Apr/2016 10:08:02] DEBUG [django.db.backends:89] (0.000) QUERY = u'SELECT "django_migrations"."app", "django_migrations"."name" FROM "django_migrations"' - PARAMS = (); args=()
[15/Apr/2016 10:11:27] ERROR [django.request:256] Internal Server Error: /startnow/
Traceback (most recent call last):
  File "/Library/Frameworks/Python.framework/Versions/2.7/lib/python2.7/site-packages/django/core/handlers/base.py", line 132, in get_response
    response = wrapped_callback(request, *callback_args, **callback_kwargs)
  File "/Users/madhurn/PycharmProjects/UMTSCellMap/startnow/views.py", line 18, in index
    handlePostMethod(request)
  File "/Users/madhurn/PycharmProjects/UMTSCellMap/startnow/views.py", line 14, in handlePostMethod
    return (sched.get_schedule())
  File "/Users/madhurn/PycharmProjects/UMTSCellMap/startnow/startnow.py", line 58, in get_schedule
    resp = self.process_request(url)
  File "/Users/madhurn/PycharmProjects/UMTSCellMap/startnow/startnow.py", line 50, in process_request
    context = ssl._create_unverfied_context()
AttributeError: 'module' object has no attribute '_create_unverfied_context'
[15/Apr/2016 10:12:21] DEBUG [django.db.backends:89] (0.001) QUERY = "\n            SELECT name, type FROM sqlite_master\n            WHERE type in ('table', 'view') AND NOT name='sqlite_sequence'\n            ORDER BY name" - PARAMS = (); args=None
[15/Apr/2016 10:12:21] DEBUG [django.db.backends:89] (0.000) QUERY = u'SELECT "django_migrations"."app", "django_migrations"."name" FROM "django_migrations"' - PARAMS = (); args=()
[15/Apr/2016 10:12:23] ERROR [django.request:256] Internal Server Error: /startnow/
Traceback (most recent call last):
  File "/Library/Frameworks/Python.framework/Versions/2.7/lib/python2.7/site-packages/django/core/handlers/base.py", line 132, in get_response
    response = wrapped_callback(request, *callback_args, **callback_kwargs)
  File "/Users/madhurn/PycharmProjects/UMTSCellMap/startnow/views.py", line 18, in index
    handlePostMethod(request)
  File "/Users/madhurn/PycharmProjects/UMTSCellMap/startnow/views.py", line 14, in handlePostMethod
    return (sched.get_schedule())
  File "/Users/madhurn/PycharmProjects/UMTSCellMap/startnow/startnow.py", line 58, in get_schedule
    resp = self.process_request(url)
  File "/Users/madhurn/PycharmProjects/UMTSCellMap/startnow/startnow.py", line 51, in process_request
    return (urllib2.urlopen(url, context=context))
  File "/opt/local/Library/Frameworks/Python.framework/Versions/2.7/lib/python2.7/urllib2.py", line 154, in urlopen
    return opener.open(url, data, timeout)
  File "/opt/local/Library/Frameworks/Python.framework/Versions/2.7/lib/python2.7/urllib2.py", line 422, in open
    req.timeout = timeout
AttributeError: 'NoneType' object has no attribute 'timeout'
[15/Apr/2016 10:13:49] DEBUG [django.db.backends:89] (0.001) QUERY = "\n            SELECT name, type FROM sqlite_master\n            WHERE type in ('table', 'view') AND NOT name='sqlite_sequence'\n            ORDER BY name" - PARAMS = (); args=None
[15/Apr/2016 10:13:49] DEBUG [django.db.backends:89] (0.000) QUERY = u'SELECT "django_migrations"."app", "django_migrations"."name" FROM "django_migrations"' - PARAMS = (); args=()
[15/Apr/2016 10:13:53] ERROR [django.request:256] Internal Server Error: /startnow/
Traceback (most recent call last):
  File "/Library/Frameworks/Python.framework/Versions/2.7/lib/python2.7/site-packages/django/core/handlers/base.py", line 132, in get_response
    response = wrapped_callback(request, *callback_args, **callback_kwargs)
  File "/Users/madhurn/PycharmProjects/UMTSCellMap/startnow/views.py", line 18, in index
    handlePostMethod(request)
  File "/Users/madhurn/PycharmProjects/UMTSCellMap/startnow/views.py", line 14, in handlePostMethod
    return (sched.get_schedule())
  File "/Users/madhurn/PycharmProjects/UMTSCellMap/startnow/startnow.py", line 59, in get_schedule
    resp = self.process_request(url)
  File "/Users/madhurn/PycharmProjects/UMTSCellMap/startnow/startnow.py", line 52, in process_request
    return (urllib2.urlopen(url, context=context))
  File "/opt/local/Library/Frameworks/Python.framework/Versions/2.7/lib/python2.7/urllib2.py", line 154, in urlopen
    return opener.open(url, data, timeout)
  File "/opt/local/Library/Frameworks/Python.framework/Versions/2.7/lib/python2.7/urllib2.py", line 422, in open
    req.timeout = timeout
AttributeError: 'NoneType' object has no attribute 'timeout'
[15/Apr/2016 10:14:16] DEBUG [django.db.backends:89] (0.001) QUERY = "\n            SELECT name, type FROM sqlite_master\n            WHERE type in ('table', 'view') AND NOT name='sqlite_sequence'\n            ORDER BY name" - PARAMS = (); args=None
[15/Apr/2016 10:14:16] DEBUG [django.db.backends:89] (0.000) QUERY = u'SELECT "django_migrations"."app", "django_migrations"."name" FROM "django_migrations"' - PARAMS = (); args=()
[15/Apr/2016 10:14:18] ERROR [django.request:256] Internal Server Error: /startnow/
Traceback (most recent call last):
  File "/Library/Frameworks/Python.framework/Versions/2.7/lib/python2.7/site-packages/django/core/handlers/base.py", line 151, in get_response
    % (callback.__module__, view_name))
ValueError: The view startnow.views.index didn't return an HttpResponse object. It returned None instead.
[15/Apr/2016 12:32:41] DEBUG [django.db.backends:89] (0.002) QUERY = "\n            SELECT name, type FROM sqlite_master\n            WHERE type in ('table', 'view') AND NOT name='sqlite_sequence'\n            ORDER BY name" - PARAMS = (); args=None
[15/Apr/2016 12:32:41] DEBUG [django.db.backends:89] (0.000) QUERY = u'SELECT "django_migrations"."app", "django_migrations"."name" FROM "django_migrations"' - PARAMS = (); args=()
[15/Apr/2016 12:44:08] ERROR [django.request:256] Internal Server Error: /startnow/
Traceback (most recent call last):
  File "/Library/Frameworks/Python.framework/Versions/2.7/lib/python2.7/site-packages/django/core/handlers/base.py", line 119, in get_response
    resolver_match = resolver.resolve(request.path_info)
  File "/Library/Frameworks/Python.framework/Versions/2.7/lib/python2.7/site-packages/django/core/urlresolvers.py", line 365, in resolve
    for pattern in self.url_patterns:
  File "/Library/Frameworks/Python.framework/Versions/2.7/lib/python2.7/site-packages/django/core/urlresolvers.py", line 401, in url_patterns
    patterns = getattr(self.urlconf_module, "urlpatterns", self.urlconf_module)
  File "/Library/Frameworks/Python.framework/Versions/2.7/lib/python2.7/site-packages/django/core/urlresolvers.py", line 395, in urlconf_module
    self._urlconf_module = import_module(self.urlconf_name)
  File "/opt/local/Library/Frameworks/Python.framework/Versions/2.7/lib/python2.7/importlib/__init__.py", line 37, in import_module
    __import__(name)
  File "/Users/madhurn/PycharmProjects/UMTSCellMap/UMTSCellMap/urls.py", line 24, in <module>
    url(r'^startnow/', include('startnow.urls', namespace="startnow")),
  File "/Library/Frameworks/Python.framework/Versions/2.7/lib/python2.7/site-packages/django/conf/urls/__init__.py", line 33, in include
    urlconf_module = import_module(urlconf_module)
  File "/opt/local/Library/Frameworks/Python.framework/Versions/2.7/lib/python2.7/importlib/__init__.py", line 37, in import_module
    __import__(name)
  File "/Users/madhurn/PycharmProjects/UMTSCellMap/startnow/urls.py", line 3, in <module>
    from views import empty
  File "/Users/madhurn/PycharmProjects/UMTSCellMap/startnow/views.py", line 4, in <module>
    from startnow import  Scheduler
  File "/Users/madhurn/PycharmProjects/UMTSCellMap/startnow/startnow.py", line 63
    for e in elems:
    ^
IndentationError: unexpected indent
[15/Apr/2016 12:44:24] ERROR [django.request:256] Internal Server Error: /startnow/
Traceback (most recent call last):
  File "/Library/Frameworks/Python.framework/Versions/2.7/lib/python2.7/site-packages/django/core/handlers/base.py", line 119, in get_response
    resolver_match = resolver.resolve(request.path_info)
  File "/Library/Frameworks/Python.framework/Versions/2.7/lib/python2.7/site-packages/django/core/urlresolvers.py", line 365, in resolve
    for pattern in self.url_patterns:
  File "/Library/Frameworks/Python.framework/Versions/2.7/lib/python2.7/site-packages/django/core/urlresolvers.py", line 401, in url_patterns
    patterns = getattr(self.urlconf_module, "urlpatterns", self.urlconf_module)
  File "/Library/Frameworks/Python.framework/Versions/2.7/lib/python2.7/site-packages/django/core/urlresolvers.py", line 395, in urlconf_module
    self._urlconf_module = import_module(self.urlconf_name)
  File "/opt/local/Library/Frameworks/Python.framework/Versions/2.7/lib/python2.7/importlib/__init__.py", line 37, in import_module
    __import__(name)
  File "/Users/madhurn/PycharmProjects/UMTSCellMap/UMTSCellMap/urls.py", line 24, in <module>
    url(r'^startnow/', include('startnow.urls', namespace="startnow")),
  File "/Library/Frameworks/Python.framework/Versions/2.7/lib/python2.7/site-packages/django/conf/urls/__init__.py", line 33, in include
    urlconf_module = import_module(urlconf_module)
  File "/opt/local/Library/Frameworks/Python.framework/Versions/2.7/lib/python2.7/importlib/__init__.py", line 37, in import_module
    __import__(name)
  File "/Users/madhurn/PycharmProjects/UMTSCellMap/startnow/urls.py", line 3, in <module>
    from views import empty
  File "/Users/madhurn/PycharmProjects/UMTSCellMap/startnow/views.py", line 4, in <module>
    from startnow import  Scheduler
  File "/Users/madhurn/PycharmProjects/UMTSCellMap/startnow/startnow.py", line 63
    for e in elems:
    ^
IndentationError: unexpected indent
[15/Apr/2016 12:44:38] ERROR [django.request:256] Internal Server Error: /startnow/
Traceback (most recent call last):
  File "/Library/Frameworks/Python.framework/Versions/2.7/lib/python2.7/site-packages/django/core/handlers/base.py", line 119, in get_response
    resolver_match = resolver.resolve(request.path_info)
  File "/Library/Frameworks/Python.framework/Versions/2.7/lib/python2.7/site-packages/django/core/urlresolvers.py", line 365, in resolve
    for pattern in self.url_patterns:
  File "/Library/Frameworks/Python.framework/Versions/2.7/lib/python2.7/site-packages/django/core/urlresolvers.py", line 401, in url_patterns
    patterns = getattr(self.urlconf_module, "urlpatterns", self.urlconf_module)
  File "/Library/Frameworks/Python.framework/Versions/2.7/lib/python2.7/site-packages/django/core/urlresolvers.py", line 395, in urlconf_module
    self._urlconf_module = import_module(self.urlconf_name)
  File "/opt/local/Library/Frameworks/Python.framework/Versions/2.7/lib/python2.7/importlib/__init__.py", line 37, in import_module
    __import__(name)
  File "/Users/madhurn/PycharmProjects/UMTSCellMap/UMTSCellMap/urls.py", line 24, in <module>
    url(r'^startnow/', include('startnow.urls', namespace="startnow")),
  File "/Library/Frameworks/Python.framework/Versions/2.7/lib/python2.7/site-packages/django/conf/urls/__init__.py", line 33, in include
    urlconf_module = import_module(urlconf_module)
  File "/opt/local/Library/Frameworks/Python.framework/Versions/2.7/lib/python2.7/importlib/__init__.py", line 37, in import_module
    __import__(name)
  File "/Users/madhurn/PycharmProjects/UMTSCellMap/startnow/urls.py", line 3, in <module>
    from views import empty
  File "/Users/madhurn/PycharmProjects/UMTSCellMap/startnow/views.py", line 4, in <module>
    from startnow import  Scheduler
  File "/Users/madhurn/PycharmProjects/UMTSCellMap/startnow/startnow.py", line 63
    for e in elems:
    ^
IndentationError: unexpected indent
[15/Apr/2016 12:44:40] ERROR [django.request:256] Internal Server Error: /startnow/
Traceback (most recent call last):
  File "/Library/Frameworks/Python.framework/Versions/2.7/lib/python2.7/site-packages/django/core/handlers/base.py", line 119, in get_response
    resolver_match = resolver.resolve(request.path_info)
  File "/Library/Frameworks/Python.framework/Versions/2.7/lib/python2.7/site-packages/django/core/urlresolvers.py", line 365, in resolve
    for pattern in self.url_patterns:
  File "/Library/Frameworks/Python.framework/Versions/2.7/lib/python2.7/site-packages/django/core/urlresolvers.py", line 401, in url_patterns
    patterns = getattr(self.urlconf_module, "urlpatterns", self.urlconf_module)
  File "/Library/Frameworks/Python.framework/Versions/2.7/lib/python2.7/site-packages/django/core/urlresolvers.py", line 395, in urlconf_module
    self._urlconf_module = import_module(self.urlconf_name)
  File "/opt/local/Library/Frameworks/Python.framework/Versions/2.7/lib/python2.7/importlib/__init__.py", line 37, in import_module
    __import__(name)
  File "/Users/madhurn/PycharmProjects/UMTSCellMap/UMTSCellMap/urls.py", line 24, in <module>
    url(r'^startnow/', include('startnow.urls', namespace="startnow")),
  File "/Library/Frameworks/Python.framework/Versions/2.7/lib/python2.7/site-packages/django/conf/urls/__init__.py", line 33, in include
    urlconf_module = import_module(urlconf_module)
  File "/opt/local/Library/Frameworks/Python.framework/Versions/2.7/lib/python2.7/importlib/__init__.py", line 37, in import_module
    __import__(name)
  File "/Users/madhurn/PycharmProjects/UMTSCellMap/startnow/urls.py", line 3, in <module>
    from views import empty
  File "/Users/madhurn/PycharmProjects/UMTSCellMap/startnow/views.py", line 4, in <module>
    from startnow import  Scheduler
  File "/Users/madhurn/PycharmProjects/UMTSCellMap/startnow/startnow.py", line 63
    for e in elems:
    ^
IndentationError: unexpected indent
[15/Apr/2016 12:45:40] ERROR [django.request:256] Internal Server Error: /startnow/
Traceback (most recent call last):
  File "/Library/Frameworks/Python.framework/Versions/2.7/lib/python2.7/site-packages/django/core/handlers/base.py", line 119, in get_response
    resolver_match = resolver.resolve(request.path_info)
  File "/Library/Frameworks/Python.framework/Versions/2.7/lib/python2.7/site-packages/django/core/urlresolvers.py", line 365, in resolve
    for pattern in self.url_patterns:
  File "/Library/Frameworks/Python.framework/Versions/2.7/lib/python2.7/site-packages/django/core/urlresolvers.py", line 401, in url_patterns
    patterns = getattr(self.urlconf_module, "urlpatterns", self.urlconf_module)
  File "/Library/Frameworks/Python.framework/Versions/2.7/lib/python2.7/site-packages/django/core/urlresolvers.py", line 395, in urlconf_module
    self._urlconf_module = import_module(self.urlconf_name)
  File "/opt/local/Library/Frameworks/Python.framework/Versions/2.7/lib/python2.7/importlib/__init__.py", line 37, in import_module
    __import__(name)
  File "/Users/madhurn/PycharmProjects/UMTSCellMap/UMTSCellMap/urls.py", line 24, in <module>
    url(r'^startnow/', include('startnow.urls', namespace="startnow")),
  File "/Library/Frameworks/Python.framework/Versions/2.7/lib/python2.7/site-packages/django/conf/urls/__init__.py", line 33, in include
    urlconf_module = import_module(urlconf_module)
  File "/opt/local/Library/Frameworks/Python.framework/Versions/2.7/lib/python2.7/importlib/__init__.py", line 37, in import_module
    __import__(name)
  File "/Users/madhurn/PycharmProjects/UMTSCellMap/startnow/urls.py", line 3, in <module>
    from views import empty
  File "/Users/madhurn/PycharmProjects/UMTSCellMap/startnow/views.py", line 4, in <module>
    from startnow import  Scheduler
  File "/Users/madhurn/PycharmProjects/UMTSCellMap/startnow/startnow.py", line 63
    for e in elems:
    ^
IndentationError: unexpected indent
[15/Apr/2016 12:46:31] ERROR [django.request:256] Internal Server Error: /startnow/
Traceback (most recent call last):
  File "/Library/Frameworks/Python.framework/Versions/2.7/lib/python2.7/site-packages/django/core/handlers/base.py", line 119, in get_response
    resolver_match = resolver.resolve(request.path_info)
  File "/Library/Frameworks/Python.framework/Versions/2.7/lib/python2.7/site-packages/django/core/urlresolvers.py", line 365, in resolve
    for pattern in self.url_patterns:
  File "/Library/Frameworks/Python.framework/Versions/2.7/lib/python2.7/site-packages/django/core/urlresolvers.py", line 401, in url_patterns
    patterns = getattr(self.urlconf_module, "urlpatterns", self.urlconf_module)
  File "/Library/Frameworks/Python.framework/Versions/2.7/lib/python2.7/site-packages/django/core/urlresolvers.py", line 395, in urlconf_module
    self._urlconf_module = import_module(self.urlconf_name)
  File "/opt/local/Library/Frameworks/Python.framework/Versions/2.7/lib/python2.7/importlib/__init__.py", line 37, in import_module
    __import__(name)
  File "/Users/madhurn/PycharmProjects/UMTSCellMap/UMTSCellMap/urls.py", line 24, in <module>
    url(r'^startnow/', include('startnow.urls', namespace="startnow")),
  File "/Library/Frameworks/Python.framework/Versions/2.7/lib/python2.7/site-packages/django/conf/urls/__init__.py", line 33, in include
    urlconf_module = import_module(urlconf_module)
  File "/opt/local/Library/Frameworks/Python.framework/Versions/2.7/lib/python2.7/importlib/__init__.py", line 37, in import_module
    __import__(name)
  File "/Users/madhurn/PycharmProjects/UMTSCellMap/startnow/urls.py", line 3, in <module>
    from views import empty
  File "/Users/madhurn/PycharmProjects/UMTSCellMap/startnow/views.py", line 4, in <module>
    from startnow import  Scheduler
  File "/Users/madhurn/PycharmProjects/UMTSCellMap/startnow/startnow.py", line 65
    for e in elems:
    ^
IndentationError: unexpected indent
[15/Apr/2016 12:47:01] DEBUG [django.db.backends:89] (0.001) QUERY = "\n            SELECT name, type FROM sqlite_master\n            WHERE type in ('table', 'view') AND NOT name='sqlite_sequence'\n            ORDER BY name" - PARAMS = (); args=None
[15/Apr/2016 12:47:01] DEBUG [django.db.backends:89] (0.000) QUERY = u'SELECT "django_migrations"."app", "django_migrations"."name" FROM "django_migrations"' - PARAMS = (); args=()
[15/Apr/2016 12:47:05] ERROR [django.request:256] Internal Server Error: /startnow/
Traceback (most recent call last):
  File "/Library/Frameworks/Python.framework/Versions/2.7/lib/python2.7/site-packages/django/core/handlers/base.py", line 119, in get_response
    resolver_match = resolver.resolve(request.path_info)
  File "/Library/Frameworks/Python.framework/Versions/2.7/lib/python2.7/site-packages/django/core/urlresolvers.py", line 365, in resolve
    for pattern in self.url_patterns:
  File "/Library/Frameworks/Python.framework/Versions/2.7/lib/python2.7/site-packages/django/core/urlresolvers.py", line 401, in url_patterns
    patterns = getattr(self.urlconf_module, "urlpatterns", self.urlconf_module)
  File "/Library/Frameworks/Python.framework/Versions/2.7/lib/python2.7/site-packages/django/core/urlresolvers.py", line 395, in urlconf_module
    self._urlconf_module = import_module(self.urlconf_name)
  File "/opt/local/Library/Frameworks/Python.framework/Versions/2.7/lib/python2.7/importlib/__init__.py", line 37, in import_module
    __import__(name)
  File "/Users/madhurn/PycharmProjects/UMTSCellMap/UMTSCellMap/urls.py", line 24, in <module>
    url(r'^startnow/', include('startnow.urls', namespace="startnow")),
  File "/Library/Frameworks/Python.framework/Versions/2.7/lib/python2.7/site-packages/django/conf/urls/__init__.py", line 33, in include
    urlconf_module = import_module(urlconf_module)
  File "/opt/local/Library/Frameworks/Python.framework/Versions/2.7/lib/python2.7/importlib/__init__.py", line 37, in import_module
    __import__(name)
  File "/Users/madhurn/PycharmProjects/UMTSCellMap/startnow/urls.py", line 3, in <module>
    from views import empty
  File "/Users/madhurn/PycharmProjects/UMTSCellMap/startnow/views.py", line 4, in <module>
    from startnow import  Scheduler
  File "/Users/madhurn/PycharmProjects/UMTSCellMap/startnow/startnow.py", line 65
    for e in elems:
    ^
IndentationError: unexpected indent
[15/Apr/2016 12:47:48] DEBUG [django.db.backends:89] (0.001) QUERY = "\n            SELECT name, type FROM sqlite_master\n            WHERE type in ('table', 'view') AND NOT name='sqlite_sequence'\n            ORDER BY name" - PARAMS = (); args=None
[15/Apr/2016 12:47:48] DEBUG [django.db.backends:89] (0.000) QUERY = u'SELECT "django_migrations"."app", "django_migrations"."name" FROM "django_migrations"' - PARAMS = (); args=()
[15/Apr/2016 12:48:02] ERROR [django.request:256] Internal Server Error: /startnow/
Traceback (most recent call last):
  File "/Library/Frameworks/Python.framework/Versions/2.7/lib/python2.7/site-packages/django/core/handlers/base.py", line 132, in get_response
    response = wrapped_callback(request, *callback_args, **callback_kwargs)
  File "/Users/madhurn/PycharmProjects/UMTSCellMap/startnow/views.py", line 18, in index
    handlePostMethod(request)
  File "/Users/madhurn/PycharmProjects/UMTSCellMap/startnow/views.py", line 14, in handlePostMethod
    return (sched.get_schedule())
  File "/Users/madhurn/PycharmProjects/UMTSCellMap/startnow/startnow.py", line 78, in get_schedule
    resp = self.process_request(url)
  File "/Users/madhurn/PycharmProjects/UMTSCellMap/startnow/startnow.py", line 59, in process_request
    status = repsonse['status']
NameError: global name 'repsonse' is not defined
[15/Apr/2016 12:48:23] DEBUG [django.db.backends:89] (0.001) QUERY = "\n            SELECT name, type FROM sqlite_master\n            WHERE type in ('table', 'view') AND NOT name='sqlite_sequence'\n            ORDER BY name" - PARAMS = (); args=None
[15/Apr/2016 12:48:23] DEBUG [django.db.backends:89] (0.000) QUERY = u'SELECT "django_migrations"."app", "django_migrations"."name" FROM "django_migrations"' - PARAMS = (); args=()
[15/Apr/2016 12:48:28] ERROR [django.request:256] Internal Server Error: /startnow/
Traceback (most recent call last):
  File "/Library/Frameworks/Python.framework/Versions/2.7/lib/python2.7/site-packages/django/core/handlers/base.py", line 132, in get_response
    response = wrapped_callback(request, *callback_args, **callback_kwargs)
  File "/Users/madhurn/PycharmProjects/UMTSCellMap/startnow/views.py", line 18, in index
    handlePostMethod(request)
  File "/Users/madhurn/PycharmProjects/UMTSCellMap/startnow/views.py", line 14, in handlePostMethod
    return (sched.get_schedule())
  File "/Users/madhurn/PycharmProjects/UMTSCellMap/startnow/startnow.py", line 78, in get_schedule
    resp = self.process_request(url)
  File "/Users/madhurn/PycharmProjects/UMTSCellMap/startnow/startnow.py", line 68, in process_request
    "Duration taken for url {} is {}".format(url, duraiton))
NameError: global name 'duraiton' is not defined
[15/Apr/2016 12:48:41] DEBUG [django.db.backends:89] (0.001) QUERY = "\n            SELECT name, type FROM sqlite_master\n            WHERE type in ('table', 'view') AND NOT name='sqlite_sequence'\n            ORDER BY name" - PARAMS = (); args=None
[15/Apr/2016 12:48:41] DEBUG [django.db.backends:89] (0.000) QUERY = u'SELECT "django_migrations"."app", "django_migrations"."name" FROM "django_migrations"' - PARAMS = (); args=()
[15/Apr/2016 12:49:00] ERROR [django.request:256] Internal Server Error: /startnow/
Traceback (most recent call last):
  File "/Library/Frameworks/Python.framework/Versions/2.7/lib/python2.7/site-packages/django/core/handlers/base.py", line 132, in get_response
    response = wrapped_callback(request, *callback_args, **callback_kwargs)
  File "/Users/madhurn/PycharmProjects/UMTSCellMap/startnow/views.py", line 18, in index
    handlePostMethod(request)
  File "/Users/madhurn/PycharmProjects/UMTSCellMap/startnow/views.py", line 14, in handlePostMethod
    return (sched.get_schedule())
  File "/Users/madhurn/PycharmProjects/UMTSCellMap/startnow/startnow.py", line 79, in get_schedule
    print resp.read()
AttributeError: 'str' object has no attribute 'read'
[15/Apr/2016 12:49:25] DEBUG [django.db.backends:89] (0.001) QUERY = "\n            SELECT name, type FROM sqlite_master\n            WHERE type in ('table', 'view') AND NOT name='sqlite_sequence'\n            ORDER BY name" - PARAMS = (); args=None
[15/Apr/2016 12:49:25] DEBUG [django.db.backends:89] (0.000) QUERY = u'SELECT "django_migrations"."app", "django_migrations"."name" FROM "django_migrations"' - PARAMS = (); args=()
[15/Apr/2016 12:49:52] ERROR [django.request:256] Internal Server Error: /startnow/
Traceback (most recent call last):
  File "/Library/Frameworks/Python.framework/Versions/2.7/lib/python2.7/site-packages/django/core/handlers/base.py", line 151, in get_response
    % (callback.__module__, view_name))
ValueError: The view startnow.views.index didn't return an HttpResponse object. It returned None instead.
[15/Apr/2016 12:50:39] ERROR [django.request:256] Internal Server Error: /startnow/
Traceback (most recent call last):
  File "/Library/Frameworks/Python.framework/Versions/2.7/lib/python2.7/site-packages/django/core/handlers/base.py", line 151, in get_response
    % (callback.__module__, view_name))
ValueError: The view startnow.views.index didn't return an HttpResponse object. It returned None instead.
[15/Apr/2016 12:52:17] ERROR [django.request:256] Internal Server Error: /startnow/
Traceback (most recent call last):
  File "/Library/Frameworks/Python.framework/Versions/2.7/lib/python2.7/site-packages/django/core/handlers/base.py", line 151, in get_response
    % (callback.__module__, view_name))
ValueError: The view startnow.views.index didn't return an HttpResponse object. It returned None instead.
[15/Apr/2016 12:52:30] ERROR [django.request:256] Internal Server Error: /startnow/
Traceback (most recent call last):
  File "/Library/Frameworks/Python.framework/Versions/2.7/lib/python2.7/site-packages/django/core/handlers/base.py", line 151, in get_response
    % (callback.__module__, view_name))
ValueError: The view startnow.views.index didn't return an HttpResponse object. It returned None instead.
[15/Apr/2016 12:53:16] DEBUG [django.db.backends:89] (0.001) QUERY = "\n            SELECT name, type FROM sqlite_master\n            WHERE type in ('table', 'view') AND NOT name='sqlite_sequence'\n            ORDER BY name" - PARAMS = (); args=None
[15/Apr/2016 12:53:16] DEBUG [django.db.backends:89] (0.000) QUERY = u'SELECT "django_migrations"."app", "django_migrations"."name" FROM "django_migrations"' - PARAMS = (); args=()
[15/Apr/2016 12:54:23] ERROR [django.request:256] Internal Server Error: /startnow/
Traceback (most recent call last):
  File "/Library/Frameworks/Python.framework/Versions/2.7/lib/python2.7/site-packages/django/core/handlers/base.py", line 151, in get_response
    % (callback.__module__, view_name))
ValueError: The view startnow.views.index didn't return an HttpResponse object. It returned None instead.
[15/Apr/2016 12:55:48] ERROR [django.request:256] Internal Server Error: /startnow/
Traceback (most recent call last):
  File "/Library/Frameworks/Python.framework/Versions/2.7/lib/python2.7/site-packages/django/core/handlers/base.py", line 151, in get_response
    % (callback.__module__, view_name))
ValueError: The view startnow.views.index didn't return an HttpResponse object. It returned None instead.
[16/Apr/2016 03:05:26] ERROR [django.request:256] Internal Server Error: /startnow/
Traceback (most recent call last):
  File "/Library/Frameworks/Python.framework/Versions/2.7/lib/python2.7/site-packages/django/core/handlers/base.py", line 151, in get_response
    % (callback.__module__, view_name))
ValueError: The view startnow.views.index didn't return an HttpResponse object. It returned None instead.
[16/Apr/2016 05:05:35] DEBUG [django.db.backends:89] (0.003) QUERY = "\n            SELECT name, type FROM sqlite_master\n            WHERE type in ('table', 'view') AND NOT name='sqlite_sequence'\n            ORDER BY name" - PARAMS = (); args=None
[16/Apr/2016 05:05:35] DEBUG [django.db.backends:89] (0.000) QUERY = u'SELECT "django_migrations"."app", "django_migrations"."name" FROM "django_migrations"' - PARAMS = (); args=()
[16/Apr/2016 07:35:45] DEBUG [django.db.backends:89] (0.002) QUERY = "\n            SELECT name, type FROM sqlite_master\n            WHERE type in ('table', 'view') AND NOT name='sqlite_sequence'\n            ORDER BY name" - PARAMS = (); args=None
[16/Apr/2016 07:35:45] DEBUG [django.db.backends:89] (0.000) QUERY = u'SELECT "django_migrations"."app", "django_migrations"."name" FROM "django_migrations"' - PARAMS = (); args=()
[16/Apr/2016 07:38:10] ERROR [django.request:256] Internal Server Error: /startnow/
Traceback (most recent call last):
  File "/Library/Frameworks/Python.framework/Versions/2.7/lib/python2.7/site-packages/django/core/handlers/base.py", line 119, in get_response
    resolver_match = resolver.resolve(request.path_info)
  File "/Library/Frameworks/Python.framework/Versions/2.7/lib/python2.7/site-packages/django/core/urlresolvers.py", line 365, in resolve
    for pattern in self.url_patterns:
  File "/Library/Frameworks/Python.framework/Versions/2.7/lib/python2.7/site-packages/django/core/urlresolvers.py", line 401, in url_patterns
    patterns = getattr(self.urlconf_module, "urlpatterns", self.urlconf_module)
  File "/Library/Frameworks/Python.framework/Versions/2.7/lib/python2.7/site-packages/django/core/urlresolvers.py", line 395, in urlconf_module
    self._urlconf_module = import_module(self.urlconf_name)
  File "/opt/local/Library/Frameworks/Python.framework/Versions/2.7/lib/python2.7/importlib/__init__.py", line 37, in import_module
    __import__(name)
  File "/Users/madhurn/PycharmProjects/UMTSCellMap/UMTSCellMap/urls.py", line 24, in <module>
    url(r'^startnow/', include('startnow.urls', namespace="startnow")),
  File "/Library/Frameworks/Python.framework/Versions/2.7/lib/python2.7/site-packages/django/conf/urls/__init__.py", line 33, in include
    urlconf_module = import_module(urlconf_module)
  File "/opt/local/Library/Frameworks/Python.framework/Versions/2.7/lib/python2.7/importlib/__init__.py", line 37, in import_module
    __import__(name)
  File "/Users/madhurn/PycharmProjects/UMTSCellMap/startnow/urls.py", line 3, in <module>
    from views import empty
  File "/Users/madhurn/PycharmProjects/UMTSCellMap/startnow/views.py", line 4, in <module>
    from startnow import  Scheduler
  File "/Users/madhurn/PycharmProjects/UMTSCellMap/startnow/startnow.py", line 9, in <module>
    from request_processor import RequestProcessor
  File "/Users/madhurn/PycharmProjects/UMTSCellMap/startnow/request_processor.py", line 9
    def process_request(self)
                            ^
SyntaxError: invalid syntax
[16/Apr/2016 07:38:34] ERROR [django.request:256] Internal Server Error: /startnow/
Traceback (most recent call last):
  File "/Library/Frameworks/Python.framework/Versions/2.7/lib/python2.7/site-packages/django/core/handlers/base.py", line 132, in get_response
    response = wrapped_callback(request, *callback_args, **callback_kwargs)
  File "/Users/madhurn/PycharmProjects/UMTSCellMap/startnow/views.py", line 18, in index
    handlePostMethod(request)
  File "/Users/madhurn/PycharmProjects/UMTSCellMap/startnow/views.py", line 14, in handlePostMethod
    return (sched.get_schedule())
  File "/Users/madhurn/PycharmProjects/UMTSCellMap/startnow/startnow.py", line 31, in get_schedule
    url_proc = UrlProcessor(self.orig_lat, self.orig_lng, self.dest_lat, self.dest_lng)
TypeError: __init__() takes exactly 1 argument (5 given)
[16/Apr/2016 07:39:27] DEBUG [django.db.backends:89] (0.001) QUERY = "\n            SELECT name, type FROM sqlite_master\n            WHERE type in ('table', 'view') AND NOT name='sqlite_sequence'\n            ORDER BY name" - PARAMS = (); args=None
[16/Apr/2016 07:39:27] DEBUG [django.db.backends:89] (0.000) QUERY = u'SELECT "django_migrations"."app", "django_migrations"."name" FROM "django_migrations"' - PARAMS = (); args=()
[16/Apr/2016 07:40:04] ERROR [django.request:256] Internal Server Error: /startnow/
Traceback (most recent call last):
  File "/Library/Frameworks/Python.framework/Versions/2.7/lib/python2.7/site-packages/django/core/handlers/base.py", line 132, in get_response
    response = wrapped_callback(request, *callback_args, **callback_kwargs)
  File "/Users/madhurn/PycharmProjects/UMTSCellMap/startnow/views.py", line 18, in index
    handlePostMethod(request)
  File "/Users/madhurn/PycharmProjects/UMTSCellMap/startnow/views.py", line 14, in handlePostMethod
    return (sched.get_schedule())
  File "/Users/madhurn/PycharmProjects/UMTSCellMap/startnow/startnow.py", line 33, in get_schedule
    url_list = url_proc.create_url(url, 24, 24)
NameError: global name 'url' is not defined
[16/Apr/2016 07:40:22] DEBUG [django.db.backends:89] (0.001) QUERY = "\n            SELECT name, type FROM sqlite_master\n            WHERE type in ('table', 'view') AND NOT name='sqlite_sequence'\n            ORDER BY name" - PARAMS = (); args=None
[16/Apr/2016 07:40:22] DEBUG [django.db.backends:89] (0.000) QUERY = u'SELECT "django_migrations"."app", "django_migrations"."name" FROM "django_migrations"' - PARAMS = (); args=()
[16/Apr/2016 07:40:28] ERROR [django.request:256] Internal Server Error: /startnow/
Traceback (most recent call last):
  File "/Library/Frameworks/Python.framework/Versions/2.7/lib/python2.7/site-packages/django/core/handlers/base.py", line 132, in get_response
    response = wrapped_callback(request, *callback_args, **callback_kwargs)
  File "/Users/madhurn/PycharmProjects/UMTSCellMap/startnow/views.py", line 18, in index
    handlePostMethod(request)
  File "/Users/madhurn/PycharmProjects/UMTSCellMap/startnow/views.py", line 14, in handlePostMethod
    return (sched.get_schedule())
  File "/Users/madhurn/PycharmProjects/UMTSCellMap/startnow/startnow.py", line 33, in get_schedule
    url_list = url_proc.create_url(24, 24)
  File "/Users/madhurn/PycharmProjects/UMTSCellMap/startnow/url_processor.py", line 45, in create_url
    curr_time = self.get_curr_time()
  File "/Users/madhurn/PycharmProjects/UMTSCellMap/startnow/url_processor.py", line 26, in get_curr_time
    return int(time.time())
NameError: global name 'time' is not defined
[16/Apr/2016 07:40:48] DEBUG [django.db.backends:89] (0.001) QUERY = "\n            SELECT name, type FROM sqlite_master\n            WHERE type in ('table', 'view') AND NOT name='sqlite_sequence'\n            ORDER BY name" - PARAMS = (); args=None
[16/Apr/2016 07:40:48] DEBUG [django.db.backends:89] (0.000) QUERY = u'SELECT "django_migrations"."app", "django_migrations"."name" FROM "django_migrations"' - PARAMS = (); args=()
[16/Apr/2016 07:40:52] ERROR [django.request:256] Internal Server Error: /startnow/
Traceback (most recent call last):
  File "/Library/Frameworks/Python.framework/Versions/2.7/lib/python2.7/site-packages/django/core/handlers/base.py", line 132, in get_response
    response = wrapped_callback(request, *callback_args, **callback_kwargs)
  File "/Users/madhurn/PycharmProjects/UMTSCellMap/startnow/views.py", line 18, in index
    handlePostMethod(request)
  File "/Users/madhurn/PycharmProjects/UMTSCellMap/startnow/views.py", line 14, in handlePostMethod
    return (sched.get_schedule())
  File "/Users/madhurn/PycharmProjects/UMTSCellMap/startnow/startnow.py", line 33, in get_schedule
    url_list = url_proc.create_url(24, 24)
  File "/Users/madhurn/PycharmProjects/UMTSCellMap/startnow/url_processor.py", line 47, in create_url
    url_list = create_url_list(url_str, url_count, curr_time, SECONDS_IN_HOUR)
NameError: global name 'create_url_list' is not defined
[16/Apr/2016 07:41:06] DEBUG [django.db.backends:89] (0.001) QUERY = "\n            SELECT name, type FROM sqlite_master\n            WHERE type in ('table', 'view') AND NOT name='sqlite_sequence'\n            ORDER BY name" - PARAMS = (); args=None
[16/Apr/2016 07:41:06] DEBUG [django.db.backends:89] (0.000) QUERY = u'SELECT "django_migrations"."app", "django_migrations"."name" FROM "django_migrations"' - PARAMS = (); args=()
[16/Apr/2016 07:41:12] ERROR [django.request:256] Internal Server Error: /startnow/
Traceback (most recent call last):
  File "/Library/Frameworks/Python.framework/Versions/2.7/lib/python2.7/site-packages/django/core/handlers/base.py", line 132, in get_response
    response = wrapped_callback(request, *callback_args, **callback_kwargs)
  File "/Users/madhurn/PycharmProjects/UMTSCellMap/startnow/views.py", line 18, in index
    handlePostMethod(request)
  File "/Users/madhurn/PycharmProjects/UMTSCellMap/startnow/views.py", line 14, in handlePostMethod
    return (sched.get_schedule())
  File "/Users/madhurn/PycharmProjects/UMTSCellMap/startnow/startnow.py", line 36, in get_schedule
    resp = self.process_request(url_list)
AttributeError: Scheduler instance has no attribute 'process_request'
[16/Apr/2016 07:41:26] DEBUG [django.db.backends:89] (0.001) QUERY = "\n            SELECT name, type FROM sqlite_master\n            WHERE type in ('table', 'view') AND NOT name='sqlite_sequence'\n            ORDER BY name" - PARAMS = (); args=None
[16/Apr/2016 07:41:26] DEBUG [django.db.backends:89] (0.000) QUERY = u'SELECT "django_migrations"."app", "django_migrations"."name" FROM "django_migrations"' - PARAMS = (); args=()
[16/Apr/2016 07:41:31] ERROR [django.request:256] Internal Server Error: /startnow/
Traceback (most recent call last):
  File "/Library/Frameworks/Python.framework/Versions/2.7/lib/python2.7/site-packages/django/core/handlers/base.py", line 132, in get_response
    response = wrapped_callback(request, *callback_args, **callback_kwargs)
  File "/Users/madhurn/PycharmProjects/UMTSCellMap/startnow/views.py", line 18, in index
    handlePostMethod(request)
  File "/Users/madhurn/PycharmProjects/UMTSCellMap/startnow/views.py", line 14, in handlePostMethod
    return (sched.get_schedule())
  File "/Users/madhurn/PycharmProjects/UMTSCellMap/startnow/startnow.py", line 35, in get_schedule
    resp = request_processor.process_request(url_list)
TypeError: process_request() takes exactly 1 argument (2 given)
[16/Apr/2016 07:42:05] DEBUG [django.db.backends:89] (0.001) QUERY = "\n            SELECT name, type FROM sqlite_master\n            WHERE type in ('table', 'view') AND NOT name='sqlite_sequence'\n            ORDER BY name" - PARAMS = (); args=None
[16/Apr/2016 07:42:05] DEBUG [django.db.backends:89] (0.000) QUERY = u'SELECT "django_migrations"."app", "django_migrations"."name" FROM "django_migrations"' - PARAMS = (); args=()
[16/Apr/2016 07:42:13] ERROR [django.request:256] Internal Server Error: /startnow/
Traceback (most recent call last):
  File "/Library/Frameworks/Python.framework/Versions/2.7/lib/python2.7/site-packages/django/core/handlers/base.py", line 132, in get_response
    response = wrapped_callback(request, *callback_args, **callback_kwargs)
  File "/Users/madhurn/PycharmProjects/UMTSCellMap/startnow/views.py", line 18, in index
    handlePostMethod(request)
  File "/Users/madhurn/PycharmProjects/UMTSCellMap/startnow/views.py", line 14, in handlePostMethod
    return (sched.get_schedule())
  File "/Users/madhurn/PycharmProjects/UMTSCellMap/startnow/startnow.py", line 35, in get_schedule
    resp = request_processor.process_requests()
  File "/Users/madhurn/PycharmProjects/UMTSCellMap/startnow/request_processor.py", line 11, in process_requests
    context = ssl._create_unverified_context()
NameError: global name 'ssl' is not defined
[16/Apr/2016 07:42:31] DEBUG [django.db.backends:89] (0.001) QUERY = "\n            SELECT name, type FROM sqlite_master\n            WHERE type in ('table', 'view') AND NOT name='sqlite_sequence'\n            ORDER BY name" - PARAMS = (); args=None
[16/Apr/2016 07:42:31] DEBUG [django.db.backends:89] (0.000) QUERY = u'SELECT "django_migrations"."app", "django_migrations"."name" FROM "django_migrations"' - PARAMS = (); args=()
[16/Apr/2016 07:42:43] ERROR [django.request:256] Internal Server Error: /startnow/
Traceback (most recent call last):
  File "/Library/Frameworks/Python.framework/Versions/2.7/lib/python2.7/site-packages/django/core/handlers/base.py", line 132, in get_response
    response = wrapped_callback(request, *callback_args, **callback_kwargs)
  File "/Users/madhurn/PycharmProjects/UMTSCellMap/startnow/views.py", line 18, in index
    handlePostMethod(request)
  File "/Users/madhurn/PycharmProjects/UMTSCellMap/startnow/views.py", line 14, in handlePostMethod
    return (sched.get_schedule())
  File "/Users/madhurn/PycharmProjects/UMTSCellMap/startnow/startnow.py", line 33, in get_schedule
    resp = request_processor.process_requests()
  File "/Users/madhurn/PycharmProjects/UMTSCellMap/startnow/request_processor.py", line 16, in process_requests
    response = simplejson.load(urllib2.urlopen(url, context=context))
NameError: global name 'urllib2' is not defined
[16/Apr/2016 07:42:52] DEBUG [django.db.backends:89] (0.001) QUERY = "\n            SELECT name, type FROM sqlite_master\n            WHERE type in ('table', 'view') AND NOT name='sqlite_sequence'\n            ORDER BY name" - PARAMS = (); args=None
[16/Apr/2016 07:42:52] DEBUG [django.db.backends:89] (0.000) QUERY = u'SELECT "django_migrations"."app", "django_migrations"."name" FROM "django_migrations"' - PARAMS = (); args=()
[16/Apr/2016 07:43:00] ERROR [django.request:256] Internal Server Error: /startnow/
Traceback (most recent call last):
  File "/Library/Frameworks/Python.framework/Versions/2.7/lib/python2.7/site-packages/django/core/handlers/base.py", line 151, in get_response
    % (callback.__module__, view_name))
ValueError: The view startnow.views.index didn't return an HttpResponse object. It returned None instead.
[16/Apr/2016 07:43:45] DEBUG [django.db.backends:89] (0.001) QUERY = "\n            SELECT name, type FROM sqlite_master\n            WHERE type in ('table', 'view') AND NOT name='sqlite_sequence'\n            ORDER BY name" - PARAMS = (); args=None
[16/Apr/2016 07:43:45] DEBUG [django.db.backends:89] (0.000) QUERY = u'SELECT "django_migrations"."app", "django_migrations"."name" FROM "django_migrations"' - PARAMS = (); args=()
[16/Apr/2016 07:44:35] ERROR [django.request:256] Internal Server Error: /startnow/
Traceback (most recent call last):
  File "/Library/Frameworks/Python.framework/Versions/2.7/lib/python2.7/site-packages/django/core/handlers/base.py", line 151, in get_response
    % (callback.__module__, view_name))
ValueError: The view startnow.views.index didn't return an HttpResponse object. It returned None instead.
[16/Apr/2016 07:45:16] DEBUG [django.db.backends:89] (0.001) QUERY = "\n            SELECT name, type FROM sqlite_master\n            WHERE type in ('table', 'view') AND NOT name='sqlite_sequence'\n            ORDER BY name" - PARAMS = (); args=None
[16/Apr/2016 07:45:16] DEBUG [django.db.backends:89] (0.000) QUERY = u'SELECT "django_migrations"."app", "django_migrations"."name" FROM "django_migrations"' - PARAMS = (); args=()
[16/Apr/2016 07:45:27] ERROR [django.request:256] Internal Server Error: /startnow/
Traceback (most recent call last):
  File "/Library/Frameworks/Python.framework/Versions/2.7/lib/python2.7/site-packages/django/core/handlers/base.py", line 151, in get_response
    % (callback.__module__, view_name))
ValueError: The view startnow.views.index didn't return an HttpResponse object. It returned None instead.
[16/Apr/2016 07:46:04] DEBUG [django.db.backends:89] (0.001) QUERY = "\n            SELECT name, type FROM sqlite_master\n            WHERE type in ('table', 'view') AND NOT name='sqlite_sequence'\n            ORDER BY name" - PARAMS = (); args=None
[16/Apr/2016 07:46:04] DEBUG [django.db.backends:89] (0.000) QUERY = u'SELECT "django_migrations"."app", "django_migrations"."name" FROM "django_migrations"' - PARAMS = (); args=()
[16/Apr/2016 07:46:07] ERROR [django.request:256] Internal Server Error: /startnow/
Traceback (most recent call last):
  File "/Library/Frameworks/Python.framework/Versions/2.7/lib/python2.7/site-packages/django/core/handlers/base.py", line 151, in get_response
    % (callback.__module__, view_name))
ValueError: The view startnow.views.index didn't return an HttpResponse object. It returned None instead.
[16/Apr/2016 07:46:34] DEBUG [django.db.backends:89] (0.001) QUERY = "\n            SELECT name, type FROM sqlite_master\n            WHERE type in ('table', 'view') AND NOT name='sqlite_sequence'\n            ORDER BY name" - PARAMS = (); args=None
[16/Apr/2016 07:46:34] DEBUG [django.db.backends:89] (0.000) QUERY = u'SELECT "django_migrations"."app", "django_migrations"."name" FROM "django_migrations"' - PARAMS = (); args=()
[16/Apr/2016 07:49:07] ERROR [django.request:256] Internal Server Error: /startnow/
Traceback (most recent call last):
  File "/Library/Frameworks/Python.framework/Versions/2.7/lib/python2.7/site-packages/django/core/handlers/base.py", line 151, in get_response
    % (callback.__module__, view_name))
ValueError: The view startnow.views.index didn't return an HttpResponse object. It returned None instead.
[16/Apr/2016 07:49:42] DEBUG [django.db.backends:89] (0.001) QUERY = "\n            SELECT name, type FROM sqlite_master\n            WHERE type in ('table', 'view') AND NOT name='sqlite_sequence'\n            ORDER BY name" - PARAMS = (); args=None
[16/Apr/2016 07:49:42] DEBUG [django.db.backends:89] (0.000) QUERY = u'SELECT "django_migrations"."app", "django_migrations"."name" FROM "django_migrations"' - PARAMS = (); args=()
[16/Apr/2016 07:49:50] ERROR [django.request:256] Internal Server Error: /startnow/
Traceback (most recent call last):
  File "/Library/Frameworks/Python.framework/Versions/2.7/lib/python2.7/site-packages/django/core/handlers/base.py", line 151, in get_response
    % (callback.__module__, view_name))
ValueError: The view startnow.views.index didn't return an HttpResponse object. It returned None instead.
[16/Apr/2016 07:50:59] DEBUG [django.db.backends:89] (0.001) QUERY = "\n            SELECT name, type FROM sqlite_master\n            WHERE type in ('table', 'view') AND NOT name='sqlite_sequence'\n            ORDER BY name" - PARAMS = (); args=None
[16/Apr/2016 07:50:59] DEBUG [django.db.backends:89] (0.000) QUERY = u'SELECT "django_migrations"."app", "django_migrations"."name" FROM "django_migrations"' - PARAMS = (); args=()
[16/Apr/2016 07:51:06] ERROR [django.request:256] Internal Server Error: /startnow/
Traceback (most recent call last):
  File "/Library/Frameworks/Python.framework/Versions/2.7/lib/python2.7/site-packages/django/core/handlers/base.py", line 151, in get_response
    % (callback.__module__, view_name))
ValueError: The view startnow.views.index didn't return an HttpResponse object. It returned None instead.
[16/Apr/2016 07:52:32] DEBUG [django.db.backends:89] (0.001) QUERY = "\n            SELECT name, type FROM sqlite_master\n            WHERE type in ('table', 'view') AND NOT name='sqlite_sequence'\n            ORDER BY name" - PARAMS = (); args=None
[16/Apr/2016 07:52:32] DEBUG [django.db.backends:89] (0.000) QUERY = u'SELECT "django_migrations"."app", "django_migrations"."name" FROM "django_migrations"' - PARAMS = (); args=()
[16/Apr/2016 07:52:37] ERROR [django.request:256] Internal Server Error: /startnow/
Traceback (most recent call last):
  File "/Library/Frameworks/Python.framework/Versions/2.7/lib/python2.7/site-packages/django/core/handlers/base.py", line 151, in get_response
    % (callback.__module__, view_name))
ValueError: The view startnow.views.index didn't return an HttpResponse object. It returned None instead.
[16/Apr/2016 07:53:45] DEBUG [django.db.backends:89] (0.001) QUERY = "\n            SELECT name, type FROM sqlite_master\n            WHERE type in ('table', 'view') AND NOT name='sqlite_sequence'\n            ORDER BY name" - PARAMS = (); args=None
[16/Apr/2016 07:53:45] DEBUG [django.db.backends:89] (0.000) QUERY = u'SELECT "django_migrations"."app", "django_migrations"."name" FROM "django_migrations"' - PARAMS = (); args=()
[16/Apr/2016 07:53:54] ERROR [django.request:256] Internal Server Error: /startnow/
Traceback (most recent call last):
  File "/Library/Frameworks/Python.framework/Versions/2.7/lib/python2.7/site-packages/django/core/handlers/base.py", line 151, in get_response
    % (callback.__module__, view_name))
ValueError: The view startnow.views.index didn't return an HttpResponse object. It returned None instead.
[16/Apr/2016 07:55:37] DEBUG [django.db.backends:89] (0.001) QUERY = "\n            SELECT name, type FROM sqlite_master\n            WHERE type in ('table', 'view') AND NOT name='sqlite_sequence'\n            ORDER BY name" - PARAMS = (); args=None
[16/Apr/2016 07:55:37] DEBUG [django.db.backends:89] (0.000) QUERY = u'SELECT "django_migrations"."app", "django_migrations"."name" FROM "django_migrations"' - PARAMS = (); args=()
[16/Apr/2016 07:55:42] ERROR [django.request:256] Internal Server Error: /startnow/
Traceback (most recent call last):
  File "/Library/Frameworks/Python.framework/Versions/2.7/lib/python2.7/site-packages/django/core/handlers/base.py", line 151, in get_response
    % (callback.__module__, view_name))
ValueError: The view startnow.views.index didn't return an HttpResponse object. It returned None instead.
[16/Apr/2016 07:56:44] DEBUG [django.db.backends:89] (0.001) QUERY = "\n            SELECT name, type FROM sqlite_master\n            WHERE type in ('table', 'view') AND NOT name='sqlite_sequence'\n            ORDER BY name" - PARAMS = (); args=None
[16/Apr/2016 07:56:44] DEBUG [django.db.backends:89] (0.000) QUERY = u'SELECT "django_migrations"."app", "django_migrations"."name" FROM "django_migrations"' - PARAMS = (); args=()
[16/Apr/2016 07:57:02] ERROR [django.request:256] Internal Server Error: /startnow/
Traceback (most recent call last):
  File "/Library/Frameworks/Python.framework/Versions/2.7/lib/python2.7/site-packages/django/core/handlers/base.py", line 151, in get_response
    % (callback.__module__, view_name))
ValueError: The view startnow.views.index didn't return an HttpResponse object. It returned None instead.
[16/Apr/2016 07:57:24] DEBUG [django.db.backends:89] (0.001) QUERY = "\n            SELECT name, type FROM sqlite_master\n            WHERE type in ('table', 'view') AND NOT name='sqlite_sequence'\n            ORDER BY name" - PARAMS = (); args=None
[16/Apr/2016 07:57:24] DEBUG [django.db.backends:89] (0.000) QUERY = u'SELECT "django_migrations"."app", "django_migrations"."name" FROM "django_migrations"' - PARAMS = (); args=()
[16/Apr/2016 07:57:52] ERROR [django.request:256] Internal Server Error: /startnow/
Traceback (most recent call last):
  File "/Library/Frameworks/Python.framework/Versions/2.7/lib/python2.7/site-packages/django/core/handlers/base.py", line 119, in get_response
    resolver_match = resolver.resolve(request.path_info)
  File "/Library/Frameworks/Python.framework/Versions/2.7/lib/python2.7/site-packages/django/core/urlresolvers.py", line 365, in resolve
    for pattern in self.url_patterns:
  File "/Library/Frameworks/Python.framework/Versions/2.7/lib/python2.7/site-packages/django/core/urlresolvers.py", line 401, in url_patterns
    patterns = getattr(self.urlconf_module, "urlpatterns", self.urlconf_module)
  File "/Library/Frameworks/Python.framework/Versions/2.7/lib/python2.7/site-packages/django/core/urlresolvers.py", line 395, in urlconf_module
    self._urlconf_module = import_module(self.urlconf_name)
  File "/opt/local/Library/Frameworks/Python.framework/Versions/2.7/lib/python2.7/importlib/__init__.py", line 37, in import_module
    __import__(name)
  File "/Users/madhurn/PycharmProjects/UMTSCellMap/UMTSCellMap/urls.py", line 24, in <module>
    url(r'^startnow/', include('startnow.urls', namespace="startnow")),
  File "/Library/Frameworks/Python.framework/Versions/2.7/lib/python2.7/site-packages/django/conf/urls/__init__.py", line 33, in include
    urlconf_module = import_module(urlconf_module)
  File "/opt/local/Library/Frameworks/Python.framework/Versions/2.7/lib/python2.7/importlib/__init__.py", line 37, in import_module
    __import__(name)
  File "/Users/madhurn/PycharmProjects/UMTSCellMap/startnow/urls.py", line 3, in <module>
    from views import empty
  File "/Users/madhurn/PycharmProjects/UMTSCellMap/startnow/views.py", line 4, in <module>
    from startnow import  Scheduler
  File "/Users/madhurn/PycharmProjects/UMTSCellMap/startnow/startnow.py", line 5, in <module>
    from request_processor import RequestProcessor
  File "/Users/madhurn/PycharmProjects/UMTSCellMap/startnow/request_processor.py", line 13
    logger.info("Processing url list {}.format(url_list))
                                                        ^
SyntaxError: EOL while scanning string literal
[16/Apr/2016 07:58:25] ERROR [django.request:256] Internal Server Error: /startnow/
Traceback (most recent call last):
  File "/Library/Frameworks/Python.framework/Versions/2.7/lib/python2.7/site-packages/django/core/handlers/base.py", line 132, in get_response
    response = wrapped_callback(request, *callback_args, **callback_kwargs)
  File "/Users/madhurn/PycharmProjects/UMTSCellMap/startnow/views.py", line 18, in index
    handlePostMethod(request)
  File "/Users/madhurn/PycharmProjects/UMTSCellMap/startnow/views.py", line 14, in handlePostMethod
    return (sched.get_schedule())
  File "/Users/madhurn/PycharmProjects/UMTSCellMap/startnow/startnow.py", line 33, in get_schedule
    resp = request_processor.process_requests()
  File "/Users/madhurn/PycharmProjects/UMTSCellMap/startnow/request_processor.py", line 13, in process_requests
    logger.info("Processing url list {}".format(url_list))
NameError: global name 'url_list' is not defined
[16/Apr/2016 07:58:32] DEBUG [django.db.backends:89] (0.001) QUERY = "\n            SELECT name, type FROM sqlite_master\n            WHERE type in ('table', 'view') AND NOT name='sqlite_sequence'\n            ORDER BY name" - PARAMS = (); args=None
[16/Apr/2016 07:58:32] DEBUG [django.db.backends:89] (0.000) QUERY = u'SELECT "django_migrations"."app", "django_migrations"."name" FROM "django_migrations"' - PARAMS = (); args=()
[16/Apr/2016 07:58:36] ERROR [django.request:256] Internal Server Error: /startnow/
Traceback (most recent call last):
  File "/Library/Frameworks/Python.framework/Versions/2.7/lib/python2.7/site-packages/django/core/handlers/base.py", line 151, in get_response
    % (callback.__module__, view_name))
ValueError: The view startnow.views.index didn't return an HttpResponse object. It returned None instead.
[16/Apr/2016 07:59:01] DEBUG [django.db.backends:89] (0.001) QUERY = "\n            SELECT name, type FROM sqlite_master\n            WHERE type in ('table', 'view') AND NOT name='sqlite_sequence'\n            ORDER BY name" - PARAMS = (); args=None
[16/Apr/2016 07:59:01] DEBUG [django.db.backends:89] (0.000) QUERY = u'SELECT "django_migrations"."app", "django_migrations"."name" FROM "django_migrations"' - PARAMS = (); args=()
[16/Apr/2016 07:59:51] ERROR [django.request:256] Internal Server Error: /startnow/
Traceback (most recent call last):
  File "/Library/Frameworks/Python.framework/Versions/2.7/lib/python2.7/site-packages/django/core/handlers/base.py", line 151, in get_response
    % (callback.__module__, view_name))
ValueError: The view startnow.views.index didn't return an HttpResponse object. It returned None instead.
[16/Apr/2016 08:00:34] ERROR [django.request:256] Internal Server Error: /startnow/
Traceback (most recent call last):
  File "/Library/Frameworks/Python.framework/Versions/2.7/lib/python2.7/site-packages/django/core/handlers/base.py", line 151, in get_response
    % (callback.__module__, view_name))
ValueError: The view startnow.views.index didn't return an HttpResponse object. It returned None instead.
[16/Apr/2016 08:01:37] ERROR [django.request:256] Internal Server Error: /startnow/
Traceback (most recent call last):
  File "/Library/Frameworks/Python.framework/Versions/2.7/lib/python2.7/site-packages/django/core/handlers/base.py", line 151, in get_response
    % (callback.__module__, view_name))
ValueError: The view startnow.views.index didn't return an HttpResponse object. It returned None instead.
[16/Apr/2016 08:26:58] DEBUG [django.db.backends:89] (0.002) QUERY = "\n            SELECT name, type FROM sqlite_master\n            WHERE type in ('table', 'view') AND NOT name='sqlite_sequence'\n            ORDER BY name" - PARAMS = (); args=None
[16/Apr/2016 08:26:58] DEBUG [django.db.backends:89] (0.000) QUERY = u'SELECT "django_migrations"."app", "django_migrations"."name" FROM "django_migrations"' - PARAMS = (); args=()
[16/Apr/2016 08:27:33] ERROR [django.request:256] Internal Server Error: /startnow/
Traceback (most recent call last):
  File "/Library/Frameworks/Python.framework/Versions/2.7/lib/python2.7/site-packages/django/core/handlers/base.py", line 151, in get_response
    % (callback.__module__, view_name))
ValueError: The view startnow.views.index didn't return an HttpResponse object. It returned None instead.
[16/Apr/2016 08:28:27] ERROR [django.request:256] Internal Server Error: /startnow/
Traceback (most recent call last):
  File "/Library/Frameworks/Python.framework/Versions/2.7/lib/python2.7/site-packages/django/core/handlers/base.py", line 151, in get_response
    % (callback.__module__, view_name))
ValueError: The view startnow.views.index didn't return an HttpResponse object. It returned None instead.
[16/Apr/2016 10:15:38] DEBUG [django.db.backends:89] (0.002) QUERY = "\n            SELECT name, type FROM sqlite_master\n            WHERE type in ('table', 'view') AND NOT name='sqlite_sequence'\n            ORDER BY name" - PARAMS = (); args=None
[16/Apr/2016 10:15:38] DEBUG [django.db.backends:89] (0.000) QUERY = u'SELECT "django_migrations"."app", "django_migrations"."name" FROM "django_migrations"' - PARAMS = (); args=()
[16/Apr/2016 12:00:28] ERROR [django.request:256] Internal Server Error: /startnow/
Traceback (most recent call last):
  File "/Library/Frameworks/Python.framework/Versions/2.7/lib/python2.7/site-packages/django/core/handlers/base.py", line 132, in get_response
    response = wrapped_callback(request, *callback_args, **callback_kwargs)
  File "/Users/madhurn/PycharmProjects/UMTSCellMap/startnow/views.py", line 18, in index
    handlePostMethod(request)
  File "/Users/madhurn/PycharmProjects/UMTSCellMap/startnow/views.py", line 14, in handlePostMethod
    return (sched.get_schedule())
  File "/Users/madhurn/PycharmProjects/UMTSCellMap/startnow/startnow.py", line 33, in get_schedule
    resp = request_processor.process_requests()
TypeError: process_requests() takes exactly 2 arguments (1 given)
[16/Apr/2016 12:14:44] DEBUG [django.db.backends:89] (0.002) QUERY = "\n            SELECT name, type FROM sqlite_master\n            WHERE type in ('table', 'view') AND NOT name='sqlite_sequence'\n            ORDER BY name" - PARAMS = (); args=None
[16/Apr/2016 12:14:44] DEBUG [django.db.backends:89] (0.000) QUERY = u'SELECT "django_migrations"."app", "django_migrations"."name" FROM "django_migrations"' - PARAMS = (); args=()
[16/Apr/2016 12:15:11] ERROR [django.request:256] Internal Server Error: /startnow/
Traceback (most recent call last):
  File "/Library/Frameworks/Python.framework/Versions/2.7/lib/python2.7/site-packages/django/core/handlers/base.py", line 132, in get_response
    response = wrapped_callback(request, *callback_args, **callback_kwargs)
  File "/Users/madhurn/PycharmProjects/UMTSCellMap/startnow/views.py", line 18, in index
    handlePostMethod(request)
  File "/Users/madhurn/PycharmProjects/UMTSCellMap/startnow/views.py", line 14, in handlePostMethod
    return (sched.get_schedule())
  File "/Users/madhurn/PycharmProjects/UMTSCellMap/startnow/startnow.py", line 33, in get_schedule
    resp = request_processor.process_requests(url_list)
  File "/Users/madhurn/PycharmProjects/UMTSCellMap/startnow/request_processor.py", line 35, in process_requests
    return (process_async_requests(url_list))
NameError: global name 'process_async_requests' is not defined
[16/Apr/2016 12:15:25] DEBUG [django.db.backends:89] (0.001) QUERY = "\n            SELECT name, type FROM sqlite_master\n            WHERE type in ('table', 'view') AND NOT name='sqlite_sequence'\n            ORDER BY name" - PARAMS = (); args=None
[16/Apr/2016 12:15:25] DEBUG [django.db.backends:89] (0.000) QUERY = u'SELECT "django_migrations"."app", "django_migrations"."name" FROM "django_migrations"' - PARAMS = (); args=()
[16/Apr/2016 12:15:28] ERROR [django.request:256] Internal Server Error: /startnow/
Traceback (most recent call last):
  File "/Library/Frameworks/Python.framework/Versions/2.7/lib/python2.7/site-packages/django/core/handlers/base.py", line 132, in get_response
    response = wrapped_callback(request, *callback_args, **callback_kwargs)
  File "/Users/madhurn/PycharmProjects/UMTSCellMap/startnow/views.py", line 18, in index
    handlePostMethod(request)
  File "/Users/madhurn/PycharmProjects/UMTSCellMap/startnow/views.py", line 14, in handlePostMethod
    return (sched.get_schedule())
  File "/Users/madhurn/PycharmProjects/UMTSCellMap/startnow/startnow.py", line 33, in get_schedule
    resp = request_processor.process_requests(url_list)
  File "/Users/madhurn/PycharmProjects/UMTSCellMap/startnow/request_processor.py", line 35, in process_requests
    return (self.process_async_requests(url_list))
TypeError: process_async_requests() takes exactly 1 argument (2 given)
[16/Apr/2016 12:15:45] DEBUG [django.db.backends:89] (0.001) QUERY = "\n            SELECT name, type FROM sqlite_master\n            WHERE type in ('table', 'view') AND NOT name='sqlite_sequence'\n            ORDER BY name" - PARAMS = (); args=None
[16/Apr/2016 12:15:45] DEBUG [django.db.backends:89] (0.000) QUERY = u'SELECT "django_migrations"."app", "django_migrations"."name" FROM "django_migrations"' - PARAMS = (); args=()
[16/Apr/2016 12:15:53] ERROR [django.request:256] Internal Server Error: /startnow/
Traceback (most recent call last):
  File "/Library/Frameworks/Python.framework/Versions/2.7/lib/python2.7/site-packages/django/core/handlers/base.py", line 132, in get_response
    response = wrapped_callback(request, *callback_args, **callback_kwargs)
  File "/Users/madhurn/PycharmProjects/UMTSCellMap/startnow/views.py", line 18, in index
    handlePostMethod(request)
  File "/Users/madhurn/PycharmProjects/UMTSCellMap/startnow/views.py", line 14, in handlePostMethod
    return (sched.get_schedule())
  File "/Users/madhurn/PycharmProjects/UMTSCellMap/startnow/startnow.py", line 33, in get_schedule
    resp = request_processor.process_requests(url_list)
  File "/Users/madhurn/PycharmProjects/UMTSCellMap/startnow/request_processor.py", line 35, in process_requests
    return (self.process_async_requests(url_list))
  File "/Users/madhurn/PycharmProjects/UMTSCellMap/startnow/request_processor.py", line 29, in process_async_requests
    result = pool.map(process_atomic_request, url_list)
NameError: global name 'process_atomic_request' is not defined
[16/Apr/2016 12:16:04] DEBUG [django.db.backends:89] (0.001) QUERY = "\n            SELECT name, type FROM sqlite_master\n            WHERE type in ('table', 'view') AND NOT name='sqlite_sequence'\n            ORDER BY name" - PARAMS = (); args=None
[16/Apr/2016 12:16:04] DEBUG [django.db.backends:89] (0.000) QUERY = u'SELECT "django_migrations"."app", "django_migrations"."name" FROM "django_migrations"' - PARAMS = (); args=()
[16/Apr/2016 12:16:08] ERROR [django.request:256] Internal Server Error: /startnow/
Traceback (most recent call last):
  File "/Library/Frameworks/Python.framework/Versions/2.7/lib/python2.7/site-packages/django/core/handlers/base.py", line 132, in get_response
    response = wrapped_callback(request, *callback_args, **callback_kwargs)
  File "/Users/madhurn/PycharmProjects/UMTSCellMap/startnow/views.py", line 18, in index
    handlePostMethod(request)
  File "/Users/madhurn/PycharmProjects/UMTSCellMap/startnow/views.py", line 14, in handlePostMethod
    return (sched.get_schedule())
  File "/Users/madhurn/PycharmProjects/UMTSCellMap/startnow/startnow.py", line 33, in get_schedule
    resp = request_processor.process_requests(url_list)
  File "/Users/madhurn/PycharmProjects/UMTSCellMap/startnow/request_processor.py", line 35, in process_requests
    return (self.process_async_requests(url_list))
  File "/Users/madhurn/PycharmProjects/UMTSCellMap/startnow/request_processor.py", line 29, in process_async_requests
    result = pool.map(self.process_atomic_request, url_list)
  File "/opt/local/Library/Frameworks/Python.framework/Versions/2.7/lib/python2.7/multiprocessing/pool.py", line 251, in map
    return self.map_async(func, iterable, chunksize).get()
  File "/opt/local/Library/Frameworks/Python.framework/Versions/2.7/lib/python2.7/multiprocessing/pool.py", line 567, in get
    raise self._value
NameError: global name 'context' is not defined
[16/Apr/2016 12:16:47] DEBUG [django.db.backends:89] (0.001) QUERY = "\n            SELECT name, type FROM sqlite_master\n            WHERE type in ('table', 'view') AND NOT name='sqlite_sequence'\n            ORDER BY name" - PARAMS = (); args=None
[16/Apr/2016 12:16:47] DEBUG [django.db.backends:89] (0.000) QUERY = u'SELECT "django_migrations"."app", "django_migrations"."name" FROM "django_migrations"' - PARAMS = (); args=()
[16/Apr/2016 12:17:23] ERROR [django.request:256] Internal Server Error: /startnow/
Traceback (most recent call last):
  File "/Library/Frameworks/Python.framework/Versions/2.7/lib/python2.7/site-packages/django/core/handlers/base.py", line 151, in get_response
    % (callback.__module__, view_name))
ValueError: The view startnow.views.index didn't return an HttpResponse object. It returned None instead.
[16/Apr/2016 12:18:10] ERROR [django.request:256] Internal Server Error: /startnow/
Traceback (most recent call last):
  File "/Library/Frameworks/Python.framework/Versions/2.7/lib/python2.7/site-packages/django/core/handlers/base.py", line 151, in get_response
    % (callback.__module__, view_name))
ValueError: The view startnow.views.index didn't return an HttpResponse object. It returned None instead.
[16/Apr/2016 12:21:50] DEBUG [django.db.backends:89] (0.001) QUERY = "\n            SELECT name, type FROM sqlite_master\n            WHERE type in ('table', 'view') AND NOT name='sqlite_sequence'\n            ORDER BY name" - PARAMS = (); args=None
[16/Apr/2016 12:21:50] DEBUG [django.db.backends:89] (0.000) QUERY = u'SELECT "django_migrations"."app", "django_migrations"."name" FROM "django_migrations"' - PARAMS = (); args=()
[16/Apr/2016 12:22:36] ERROR [django.request:256] Internal Server Error: /startnow/
Traceback (most recent call last):
  File "/Library/Frameworks/Python.framework/Versions/2.7/lib/python2.7/site-packages/django/core/handlers/base.py", line 132, in get_response
    response = wrapped_callback(request, *callback_args, **callback_kwargs)
  File "/Users/madhurn/PycharmProjects/UMTSCellMap/startnow/views.py", line 18, in index
    handlePostMethod(request)
  File "/Users/madhurn/PycharmProjects/UMTSCellMap/startnow/views.py", line 14, in handlePostMethod
    return (sched.get_schedule())
  File "/Users/madhurn/PycharmProjects/UMTSCellMap/startnow/startnow.py", line 33, in get_schedule
    resp = request_processor.process_requests(url_list)
  File "/Users/madhurn/PycharmProjects/UMTSCellMap/startnow/request_processor.py", line 35, in process_requests
    return (self.process_async_requests(url_list))
  File "/Users/madhurn/PycharmProjects/UMTSCellMap/startnow/request_processor.py", line 29, in process_async_requests
    result = pool.map(self.process_atomic_request, url_list)
  File "/opt/local/Library/Frameworks/Python.framework/Versions/2.7/lib/python2.7/multiprocessing/pool.py", line 251, in map
    return self.map_async(func, iterable, chunksize).get()
  File "/opt/local/Library/Frameworks/Python.framework/Versions/2.7/lib/python2.7/multiprocessing/pool.py", line 567, in get
    raise self._value
TypeError: process_atomic_request() takes exactly 3 arguments (2 given)
[16/Apr/2016 12:22:52] DEBUG [django.db.backends:89] (0.001) QUERY = "\n            SELECT name, type FROM sqlite_master\n            WHERE type in ('table', 'view') AND NOT name='sqlite_sequence'\n            ORDER BY name" - PARAMS = (); args=None
[16/Apr/2016 12:22:52] DEBUG [django.db.backends:89] (0.000) QUERY = u'SELECT "django_migrations"."app", "django_migrations"."name" FROM "django_migrations"' - PARAMS = (); args=()
[16/Apr/2016 12:22:56] ERROR [django.request:256] Internal Server Error: /startnow/
Traceback (most recent call last):
  File "/Library/Frameworks/Python.framework/Versions/2.7/lib/python2.7/site-packages/django/core/handlers/base.py", line 151, in get_response
    % (callback.__module__, view_name))
ValueError: The view startnow.views.index didn't return an HttpResponse object. It returned None instead.
[16/Apr/2016 12:27:35] DEBUG [django.db.backends:89] (0.003) QUERY = "\n            SELECT name, type FROM sqlite_master\n            WHERE type in ('table', 'view') AND NOT name='sqlite_sequence'\n            ORDER BY name" - PARAMS = (); args=None
[16/Apr/2016 12:27:35] DEBUG [django.db.backends:89] (0.000) QUERY = u'SELECT "django_migrations"."app", "django_migrations"."name" FROM "django_migrations"' - PARAMS = (); args=()
[16/Apr/2016 12:27:56] ERROR [django.request:256] Internal Server Error: /startnow/
Traceback (most recent call last):
  File "/Library/Frameworks/Python.framework/Versions/2.7/lib/python2.7/site-packages/django/core/handlers/base.py", line 132, in get_response
    response = wrapped_callback(request, *callback_args, **callback_kwargs)
  File "/Users/madhurn/PycharmProjects/UMTSCellMap/startnow/views.py", line 18, in index
    handlePostMethod(request)
  File "/Users/madhurn/PycharmProjects/UMTSCellMap/startnow/views.py", line 14, in handlePostMethod
    return (sched.get_schedule())
  File "/Users/madhurn/PycharmProjects/UMTSCellMap/startnow/startnow.py", line 36, in get_schedule
    print datetime.datetime.fromtimestamp(ts_epoch).strftime('%Y-%m-%d %H:%M:%S'), duration
NameError: global name 'datetime' is not defined
[16/Apr/2016 12:28:06] DEBUG [django.db.backends:89] (0.001) QUERY = "\n            SELECT name, type FROM sqlite_master\n            WHERE type in ('table', 'view') AND NOT name='sqlite_sequence'\n            ORDER BY name" - PARAMS = (); args=None
[16/Apr/2016 12:28:06] DEBUG [django.db.backends:89] (0.000) QUERY = u'SELECT "django_migrations"."app", "django_migrations"."name" FROM "django_migrations"' - PARAMS = (); args=()
[16/Apr/2016 12:28:11] ERROR [django.request:256] Internal Server Error: /startnow/
Traceback (most recent call last):
  File "/Library/Frameworks/Python.framework/Versions/2.7/lib/python2.7/site-packages/django/core/handlers/base.py", line 151, in get_response
    % (callback.__module__, view_name))
ValueError: The view startnow.views.index didn't return an HttpResponse object. It returned None instead.
[16/Apr/2016 13:10:22] ERROR [django.request:256] Internal Server Error: /startnow/
Traceback (most recent call last):
  File "/Library/Frameworks/Python.framework/Versions/2.7/lib/python2.7/site-packages/django/core/handlers/base.py", line 151, in get_response
    % (callback.__module__, view_name))
ValueError: The view startnow.views.index didn't return an HttpResponse object. It returned None instead.
[16/Apr/2016 13:15:02] DEBUG [django.db.backends:89] (0.002) QUERY = "\n            SELECT name, type FROM sqlite_master\n            WHERE type in ('table', 'view') AND NOT name='sqlite_sequence'\n            ORDER BY name" - PARAMS = (); args=None
[16/Apr/2016 13:15:02] DEBUG [django.db.backends:89] (0.000) QUERY = u'SELECT "django_migrations"."app", "django_migrations"."name" FROM "django_migrations"' - PARAMS = (); args=()
[16/Apr/2016 13:15:27] ERROR [django.request:256] Internal Server Error: /startnow/
Traceback (most recent call last):
  File "/Library/Frameworks/Python.framework/Versions/2.7/lib/python2.7/site-packages/django/core/handlers/base.py", line 151, in get_response
    % (callback.__module__, view_name))
ValueError: The view startnow.views.index didn't return an HttpResponse object. It returned None instead.
[16/Apr/2016 13:24:13] ERROR [django.request:256] Internal Server Error: /startnow/
Traceback (most recent call last):
  File "/Library/Frameworks/Python.framework/Versions/2.7/lib/python2.7/site-packages/django/core/handlers/base.py", line 151, in get_response
    % (callback.__module__, view_name))
ValueError: The view startnow.views.index didn't return an HttpResponse object. It returned None instead.
[16/Apr/2016 13:28:54] DEBUG [django.db.backends:89] (0.001) QUERY = "\n            SELECT name, type FROM sqlite_master\n            WHERE type in ('table', 'view') AND NOT name='sqlite_sequence'\n            ORDER BY name" - PARAMS = (); args=None
[16/Apr/2016 13:28:54] DEBUG [django.db.backends:89] (0.000) QUERY = u'SELECT "django_migrations"."app", "django_migrations"."name" FROM "django_migrations"' - PARAMS = (); args=()
[16/Apr/2016 13:39:50] DEBUG [django.db.backends:89] (0.001) QUERY = "\n            SELECT name, type FROM sqlite_master\n            WHERE type in ('table', 'view') AND NOT name='sqlite_sequence'\n            ORDER BY name" - PARAMS = (); args=None
[16/Apr/2016 13:39:50] DEBUG [django.db.backends:89] (0.000) QUERY = u'SELECT "django_migrations"."app", "django_migrations"."name" FROM "django_migrations"' - PARAMS = (); args=()
[16/Apr/2016 13:43:16] DEBUG [django.db.backends:89] (0.001) QUERY = "\n            SELECT name, type FROM sqlite_master\n            WHERE type in ('table', 'view') AND NOT name='sqlite_sequence'\n            ORDER BY name" - PARAMS = (); args=None
[16/Apr/2016 13:43:16] DEBUG [django.db.backends:89] (0.000) QUERY = u'SELECT "django_migrations"."app", "django_migrations"."name" FROM "django_migrations"' - PARAMS = (); args=()
[16/Apr/2016 13:54:58] DEBUG [django.db.backends:89] (0.001) QUERY = "\n            SELECT name, type FROM sqlite_master\n            WHERE type in ('table', 'view') AND NOT name='sqlite_sequence'\n            ORDER BY name" - PARAMS = (); args=None
[16/Apr/2016 13:54:58] DEBUG [django.db.backends:89] (0.000) QUERY = u'SELECT "django_migrations"."app", "django_migrations"."name" FROM "django_migrations"' - PARAMS = (); args=()
[16/Apr/2016 13:56:08] ERROR [django.request:256] Internal Server Error: /startnow/
Traceback (most recent call last):
  File "/Library/Frameworks/Python.framework/Versions/2.7/lib/python2.7/site-packages/django/core/handlers/base.py", line 132, in get_response
    response = wrapped_callback(request, *callback_args, **callback_kwargs)
  File "/Users/madhurn/PycharmProjects/UMTSCellMap/startnow/views.py", line 18, in index
    list = handlePostMethod(request)
  File "/Users/madhurn/PycharmProjects/UMTSCellMap/startnow/views.py", line 14, in handlePostMethod
    return (sched.get_schedule())
  File "/Users/madhurn/PycharmProjects/UMTSCellMap/startnow/startnow.py", line 34, in get_schedule
    resp = request_processor.process_requests(url_list)
  File "/Users/madhurn/PycharmProjects/UMTSCellMap/startnow/request_processor.py", line 36, in process_requests
    return (self.process_async_requests(url_list))
  File "/Users/madhurn/PycharmProjects/UMTSCellMap/startnow/request_processor.py", line 30, in process_async_requests
    result = pool.map(self.process_atomic_request, url_list)
  File "/opt/local/Library/Frameworks/Python.framework/Versions/2.7/lib/python2.7/multiprocessing/pool.py", line 251, in map
    return self.map_async(func, iterable, chunksize).get()
  File "/opt/local/Library/Frameworks/Python.framework/Versions/2.7/lib/python2.7/multiprocessing/pool.py", line 567, in get
    raise self._value
NameError: global name 'datetime' is not defined
[16/Apr/2016 13:56:17] DEBUG [django.db.backends:89] (0.001) QUERY = "\n            SELECT name, type FROM sqlite_master\n            WHERE type in ('table', 'view') AND NOT name='sqlite_sequence'\n            ORDER BY name" - PARAMS = (); args=None
[16/Apr/2016 13:56:17] DEBUG [django.db.backends:89] (0.000) QUERY = u'SELECT "django_migrations"."app", "django_migrations"."name" FROM "django_migrations"' - PARAMS = (); args=()
[16/Apr/2016 13:56:31] ERROR [django.request:256] Internal Server Error: /startnow/
Traceback (most recent call last):
  File "/Library/Frameworks/Python.framework/Versions/2.7/lib/python2.7/site-packages/django/core/handlers/base.py", line 132, in get_response
    response = wrapped_callback(request, *callback_args, **callback_kwargs)
  File "/Users/madhurn/PycharmProjects/UMTSCellMap/startnow/views.py", line 18, in index
    list = handlePostMethod(request)
  File "/Users/madhurn/PycharmProjects/UMTSCellMap/startnow/views.py", line 14, in handlePostMethod
    return (sched.get_schedule())
  File "/Users/madhurn/PycharmProjects/UMTSCellMap/startnow/startnow.py", line 34, in get_schedule
    resp = request_processor.process_requests(url_list)
  File "/Users/madhurn/PycharmProjects/UMTSCellMap/startnow/request_processor.py", line 37, in process_requests
    return (self.process_async_requests(url_list))
  File "/Users/madhurn/PycharmProjects/UMTSCellMap/startnow/request_processor.py", line 31, in process_async_requests
    result = pool.map(self.process_atomic_request, url_list)
  File "/opt/local/Library/Frameworks/Python.framework/Versions/2.7/lib/python2.7/multiprocessing/pool.py", line 251, in map
    return self.map_async(func, iterable, chunksize).get()
  File "/opt/local/Library/Frameworks/Python.framework/Versions/2.7/lib/python2.7/multiprocessing/pool.py", line 567, in get
    raise self._value
AttributeError: 'datetime.datetime' object has no attribute 'strftimea'
[16/Apr/2016 13:56:42] DEBUG [django.db.backends:89] (0.001) QUERY = "\n            SELECT name, type FROM sqlite_master\n            WHERE type in ('table', 'view') AND NOT name='sqlite_sequence'\n            ORDER BY name" - PARAMS = (); args=None
[16/Apr/2016 13:56:42] DEBUG [django.db.backends:89] (0.000) QUERY = u'SELECT "django_migrations"."app", "django_migrations"."name" FROM "django_migrations"' - PARAMS = (); args=()
[16/Apr/2016 13:56:54] ERROR [django.request:256] Internal Server Error: /startnow/
Traceback (most recent call last):
  File "/Library/Frameworks/Python.framework/Versions/2.7/lib/python2.7/site-packages/django/core/handlers/base.py", line 132, in get_response
    response = wrapped_callback(request, *callback_args, **callback_kwargs)
  File "/Users/madhurn/PycharmProjects/UMTSCellMap/startnow/views.py", line 18, in index
    list = handlePostMethod(request)
  File "/Users/madhurn/PycharmProjects/UMTSCellMap/startnow/views.py", line 14, in handlePostMethod
    return (sched.get_schedule())
  File "/Users/madhurn/PycharmProjects/UMTSCellMap/startnow/startnow.py", line 37, in get_schedule
    logger.info("{} {}".format(datetime.datetime.fromtimestamp(ts_epoch).strftime('%Y-%m-%d %H:%M:%S'), duration))
TypeError: a float is required
[16/Apr/2016 13:58:23] DEBUG [django.db.backends:89] (0.003) QUERY = "\n            SELECT name, type FROM sqlite_master\n            WHERE type in ('table', 'view') AND NOT name='sqlite_sequence'\n            ORDER BY name" - PARAMS = (); args=None
[16/Apr/2016 13:58:23] DEBUG [django.db.backends:89] (0.000) QUERY = u'SELECT "django_migrations"."app", "django_migrations"."name" FROM "django_migrations"' - PARAMS = (); args=()
[16/Apr/2016 13:58:26] ERROR [django.request:256] Internal Server Error: /startnow/
Traceback (most recent call last):
  File "/Library/Frameworks/Python.framework/Versions/2.7/lib/python2.7/site-packages/django/core/handlers/base.py", line 119, in get_response
    resolver_match = resolver.resolve(request.path_info)
  File "/Library/Frameworks/Python.framework/Versions/2.7/lib/python2.7/site-packages/django/core/urlresolvers.py", line 365, in resolve
    for pattern in self.url_patterns:
  File "/Library/Frameworks/Python.framework/Versions/2.7/lib/python2.7/site-packages/django/core/urlresolvers.py", line 401, in url_patterns
    patterns = getattr(self.urlconf_module, "urlpatterns", self.urlconf_module)
  File "/Library/Frameworks/Python.framework/Versions/2.7/lib/python2.7/site-packages/django/core/urlresolvers.py", line 395, in urlconf_module
    self._urlconf_module = import_module(self.urlconf_name)
  File "/opt/local/Library/Frameworks/Python.framework/Versions/2.7/lib/python2.7/importlib/__init__.py", line 37, in import_module
    __import__(name)
  File "/Users/madhurn/PycharmProjects/UMTSCellMap/UMTSCellMap/urls.py", line 24, in <module>
    url(r'^startnow/', include('startnow.urls', namespace="startnow")),
  File "/Library/Frameworks/Python.framework/Versions/2.7/lib/python2.7/site-packages/django/conf/urls/__init__.py", line 33, in include
    urlconf_module = import_module(urlconf_module)
  File "/opt/local/Library/Frameworks/Python.framework/Versions/2.7/lib/python2.7/importlib/__init__.py", line 37, in import_module
    __import__(name)
  File "/Users/madhurn/PycharmProjects/UMTSCellMap/startnow/urls.py", line 3, in <module>
    from views import empty
  File "/Users/madhurn/PycharmProjects/UMTSCellMap/startnow/views.py", line 4, in <module>
    from startnow import  Scheduler
  File "/Users/madhurn/PycharmProjects/UMTSCellMap/startnow/startnow.py", line 37
    logger.info("{} {}".ts_epoch, duration))
                                           ^
SyntaxError: invalid syntax
